Workbook

Sheet SHU TB 2025
I1: =COUNT(I5:I100) -> 93 | J1: =SUM(J5:J100) -> 31032935 | K1: =SUM(K5:K100) -> 31032935 | L1: =SUM(L5:L100) -> 31032935 | M1: =SUM(M5:M100) -> 93098804 | O1: 1.5516467e+08 | P1: SHU TB 2025
J2: =J1-R3 -> -4.8428774e-08 | K2: =K1-R3 -> 0 | L2: =L1-R3 -> 0 | N2: 0.4 | O2: =O1*N2 -> 62065869 | P2: Cadangan
I3: PENERIMAAN SHU TB 2025 | N3: 0.6 | O3: =O1*N3 -> 93098804 | P3: Bagi Anggota | R3: =O3/3 -> 31032935
A4: 2024 | B4: NIK | D4: NAMA KARYAWAN | E4: KET | F4: WILAYAH | G4: L/P | I4: No | J4: SHU Anggota | K4: SHU Kontribusi | L4: SHU RusWas | M4: Terima
A5: 1 | B5: T.205232 | C5: MANAJER | D5: ABDUL RAHMAN, SE | E5: AKTIF | F5: GRESIK | G5: L | I5: 1 | J5: =$R$3/($I$1-3) -> 344810.38 | K5: =IFERROR((VLOOKUP(D5,Sheet1!$B$3:$C$58,2,0)*$R$3),0) -> 569824.13 | L5: 0 | M5: =SUM(J5:L5) -> 914634.52
A6: 2 | B6: T.208254 | C6: ASMAN | D6: ACH. WACHYUDI | E6: AKTIF | F6: GRESIK | G6: L | I6: 2 | J6: =$R$3/($I$1-3) -> 344810.38 | K6: =IFERROR((VLOOKUP(D6,Sheet1!$B$3:$C$58,2,0)*$R$3),0) -> 1020655.6 | L6: =$R$3*27% -> 8378892.3 | M6: =SUM(J6:L6) -> 9744358.3
A7: 3 | B7: T.213284 | C7: STAF | D7: ADY PURNOMO | E7: AKTIF | F7: GRESIK | G7: L | I7: 3 | J7: =$R$3/($I$1-3) -> 344810.38 | K7: =IFERROR((VLOOKUP(D7,Sheet1!$B$3:$C$58,2,0)*$R$3),0) -> 0 | L7: 0 | M7: =SUM(J7:L7) -> 344810.38
A8: 4 | B8: T.217305 | C8: STAF | D8: AENAL DARWIS | E8: AKTIF | F8: MAKASSAR | G8: L | I8: 4 | J8: =$R$3/($I$1-3) -> 344810.38 | K8: =IFERROR((VLOOKUP(D8,Sheet1!$B$3:$C$58,2,0)*$R$3),0) -> 0 | L8: 0 | M8: =SUM(J8:L8) -> 344810.38
A9: 5 | B9: T.221311 | C9: STAF | D9: AGHNIA PUTRI RUSIANTO | E9: AKTIF | F9: MAKASSAR | G9: L | I9: 5 | J9: =$R$3/($I$1-3) -> 344810.38 | K9: =IFERROR((VLOOKUP(D9,Sheet1!$B$3:$C$58,2,0)*$R$3),0) -> 0 | L9: 0 | M9: =SUM(J9:L9) -> 344810.38
A10: 6 | B10: T.205220 | C10: ASMAN | D10: AHMAD MUKHLIS K. | E10: AKTIF | F10: GRESIK | G10: P | I10: 6 | J10: =$R$3/($I$1-3) -> 344810.38 | K10: =IFERROR((VLOOKUP(D10,Sheet1!$B$3:$C$58,2,0)*$R$3),0) -> 797753.79 | L10: 0 | M10: =SUM(J10:L10) -> 1142564.2
A11: 7 | B11: T.211279 | C11: STAF | D11: ARDHI YUNANTO | E11: AKTIF | F11: GRESIK | G11: L | I11: 7 | J11: =$R$3/($I$1-3) -> 344810.38 | K11: =IFERROR((VLOOKUP(D11,Sheet1!$B$3:$C$58,2,0)*$R$3),0) -> 284912.07 | L11: 0 | M11: =SUM(J11:L11) -> 629722.45
A12: 8 | B12: T.211273 | C12: STAF | D12: ARI KUNCORO | E12: AKTIF | F12: GRESIK | G12: L | I12: 8 | J12: =$R$3/($I$1-3) -> 344810.38 | K12: =IFERROR((VLOOKUP(D12,Sheet1!$B$3:$C$58,2,0)*$R$3),0) -> 64803.529 | L12: 0 | M12: =SUM(J12:L12) -> 409613.91
A13: 9 | B13: T.210269 | C13: STAF | D13: ARI RAHAYU | E13: AKTIF | F13: GRESIK | G13: L | I13: 9 | J13: =$R$3/($I$1-3) -> 344810.38 | K13: =IFERROR((VLOOKUP(D13,Sheet1!$B$3:$C$58,2,0)*$R$3),0) -> 0 | L13: 0 | M13: =SUM(J13:L13) -> 344810.38
A14: 10 | B14: T.211275 | C14: ASMAN | D14: BAGUS ADITA | E14: AKTIF | F14: GRESIK | G14: P | I14: 10 | J14: =$R$3/($I$1-3) -> 344810.38 | K14: =IFERROR((VLOOKUP(D14,Sheet1!$B$3:$C$58,2,0)*$R$3),0) -> 1139648.3 | L14: =$R$3*25% -> 7758233.7 | M14: =SUM(J14:L14) -> 9242692.3
A15: 11 | B15: T.205239 | C15: STAF | D15: BAMBANG SYAMADJI | E15: AKTIF | F15: GRESIK | G15: L | I15: 11 | J15: =$R$3/($I$1-3) -> 344810.38 | K15: =IFERROR((VLOOKUP(D15,Sheet1!$B$3:$C$58,2,0)*$R$3),0) -> 308096.09 | L15: 0 | M15: =SUM(J15:L15) -> 652906.47
A16: 12 | B16: T.208257 | C16: STAF | D16: BURNAMA KUSUMA DR.,SE | E16: AKTIF | F16: GRESIK | G16: L | I16: 12 | J16: =$R$3/($I$1-3) -> 344810.38 | K16: =IFERROR((VLOOKUP(D16,Sheet1!$B$3:$C$58,2,0)*$R$3),0) -> 0 | L16: 0 | M16: =SUM(J16:L16) -> 344810.38
A17: 13 | B17: T.208256 | C17: ASMAN | D17: CHOIRI,SE | E17: AKTIF | F17: GRESIK | G17: L | I17: 13 | J17: =$R$3/($I$1-3) -> 344810.38 | K17: =IFERROR((VLOOKUP(D17,Sheet1!$B$3:$C$58,2,0)*$R$3),0) -> 118713.36 | L17: 0 | M17: =SUM(J17:L17) -> 463523.75
A18: 14 | B18: T.205234 | C18: STAF | D18: DANDUNG KASIATNO | E18: AKTIF | F18: GRESIK | G18: L | I18: 14 | J18: =$R$3/($I$1-3) -> 344810.38 | K18: =IFERROR((VLOOKUP(D18,Sheet1!$B$3:$C$58,2,0)*$R$3),0) -> 507534.53 | L18: 0 | M18: =SUM(J18:L18) -> 852344.92
A19: 15 | B19: T.202207 | C19: STAF | D19: DARWANTO | E19: AKTIF | F19: GRESIK | G19: L | I19: 15 | J19: =$R$3/($I$1-3) -> 344810.38 | K19: =IFERROR((VLOOKUP(D19,Sheet1!$B$3:$C$58,2,0)*$R$3),0) -> 1253613.1 | L19: 0 | M19: =SUM(J19:L19) -> 1598423.5
A20: 16 | B20: T.940161 | C20: STAF | D20: DEWI FATMAWATI | E20: AKTIF | F20: GRESIK | G20: L | I20: 16 | J20: =$R$3/($I$1-3) -> 344810.38 | K20: =IFERROR((VLOOKUP(D20,Sheet1!$B$3:$C$58,2,0)*$R$3),0) -> 0 | L20: 0 | M20: =SUM(J20:L20) -> 344810.38
A21: 17 | B21: T.211276 | C21: STAF | D21: DIAH PUSPITASARI | E21: AKTIF | F21: GRESIK | G21: P | I21: 17 | J21: =$R$3/($I$1-3) -> 344810.38 | K21: =IFERROR((VLOOKUP(D21,Sheet1!$B$3:$C$58,2,0)*$R$3),0) -> 0 | L21: =$R$3*25% -> 7758233.7 | M21: =SUM(J21:L21) -> 8103044
A22: 18 | B22: T.970200 | C22: STAF | D22: DWI RINI P, SE | E22: AKTIF | F22: GRESIK | G22: P | I22: 18 | J22: =$R$3/($I$1-3) -> 344810.38 | K22: =IFERROR((VLOOKUP(D22,Sheet1!$B$3:$C$58,2,0)*$R$3),0) -> 0 | L22: 0 | M22: =SUM(J22:L22) -> 344810.38
A23: 19 | B23: T.211277 | C23: STAF | D23: ERLY NURLIANTI | E23: AKTIF | F23: GRESIK | G23: P | I23: 19 | J23: =$R$3/($I$1-3) -> 344810.38 | K23: =IFERROR((VLOOKUP(D23,Sheet1!$B$3:$C$58,2,0)*$R$3),0) -> 307369.84 | L23: 0 | M23: =SUM(J23:L23) -> 652180.23
A24: 20 | B24: T.205213 | C24: STAF | D24: FABIAN ABDUL GAFFAR | E24: AKTIF | F24: GRESIK | G24: L | I24: 20 | J24: =$R$3/($I$1-3) -> 344810.38 | K24: =IFERROR((VLOOKUP(D24,Sheet1!$B$3:$C$58,2,0)*$R$3),0) -> 0 | L24: 0 | M24: =SUM(J24:L24) -> 344810.38
A25: 21 | B25: T.202203 | C25: STAF | D25: FADELAN CHADARIANTO | E25: AKTIF | F25: GRESIK | G25: P | I25: 21 | J25: =$R$3/($I$1-3) -> 344810.38 | K25: =IFERROR((VLOOKUP(D25,Sheet1!$B$3:$C$58,2,0)*$R$3),0) -> 858088.11 | L25: 0 | M25: =SUM(J25:L25) -> 1202898.5
A26: 22 | B26: T.205219 | C26: STAF | D26: FIFI EMMALIA,SE | E26: AKTIF | F26: GRESIK | G26: L | I26: 22 | J26: =$R$3/($I$1-3) -> 344810.38 | K26: =IFERROR((VLOOKUP(D26,Sheet1!$B$3:$C$58,2,0)*$R$3),0) -> 0 | L26: 0 | M26: =SUM(J26:L26) -> 344810.38
A27: 23 | B27: T.208252 | C27: STAF | D27: GOLIK | E27: AKTIF | F27: GRESIK | G27: L | I27: 23 | J27: =$R$3/($I$1-3) -> 344810.38 | K27: =IFERROR((VLOOKUP(D27,Sheet1!$B$3:$C$58,2,0)*$R$3),0) -> 797753.79 | L27: 0 | M27: =SUM(J27:L27) -> 1142564.2
A28: 24 | B28: T.210265 | C28: STAF | D28: HANDOKO TEJO SAPUTRO, STp. | E28: AKTIF | F28: GRESIK | G28: P | I28: 24 | J28: =$R$3/($I$1-3) -> 344810.38 | K28: =IFERROR((VLOOKUP(D28,Sheet1!$B$3:$C$58,2,0)*$R$3),0) -> 214661.69 | L28: 0 | M28: =SUM(J28:L28) -> 559472.07
A29: 25 | B29: T.210258 | C29: STAF | D29: HARI EKO SUSANTO, SE | E29: AKTIF | F29: GRESIK | G29: L | I29: 25 | J29: =$R$3/($I$1-3) -> 344810.38 | K29: =IFERROR((VLOOKUP(D29,Sheet1!$B$3:$C$58,2,0)*$R$3),0) -> 615410.06 | L29: 0 | M29: =SUM(J29:L29) -> 960220.45
A30: 26 | B30: T.940151 | C30: MANAJER | D30: HENY ISTIANA | E30: AKTIF | F30: GRESIK | G30: L | I30: 26 | J30: =$R$3/($I$1-3) -> 344810.38 | K30: =IFERROR((VLOOKUP(D30,Sheet1!$B$3:$C$58,2,0)*$R$3),0) -> 0 | L30: =$R$3*8% -> 2482634.8 | M30: =SUM(J30:L30) -> 2827445.2
A31: 27 | B31: T.990196 | C31: STAF | D31: HERMANTO | E31: AKTIF | F31: GRESIK | G31: L | I31: 27 | J31: =$R$3/($I$1-3) -> 344810.38 | K31: =IFERROR((VLOOKUP(D31,Sheet1!$B$3:$C$58,2,0)*$R$3),0) -> 616750.83 | L31: 0 | M31: =SUM(J31:L31) -> 961561.21
A32: 28 | B32: T.207247 | C32: STAF | D32: HERY PURNOMO | E32: AKTIF | F32: GRESIK | G32: L | I32: 28 | J32: =$R$3/($I$1-3) -> 344810.38 | K32: =IFERROR((VLOOKUP(D32,Sheet1!$B$3:$C$58,2,0)*$R$3),0) -> 0 | L32: 0 | M32: =SUM(J32:L32) -> 344810.38
A33: 29 | B33: T.210261 | C33: ASMAN | D33: I DEWA PUTU CANDRA K., ST | E33: AKTIF | F33: GRESIK | G33: L | I33: 29 | J33: =$R$3/($I$1-3) -> 344810.38 | K33: =IFERROR((VLOOKUP(D33,Sheet1!$B$3:$C$58,2,0)*$R$3),0) -> 556416.51 | L33: 0 | M33: =SUM(J33:L33) -> 901226.89
A34: 30 | B34: T.205218 | C34: STAF | D34: ISFA' | E34: AKTIF | F34: GRESIK | G34: L | I34: 30 | J34: =$R$3/($I$1-3) -> 344810.38 | K34: =IFERROR((VLOOKUP(D34,Sheet1!$B$3:$C$58,2,0)*$R$3),0) -> 1139648.3 | L34: 0 | M34: =SUM(J34:L34) -> 1484458.6
A35: 31 | B35: T.970175 | C35: ASMAN | D35: ITA SUDARWATI | E35: AKTIF | F35: GRESIK | G35: P | I35: 31 | J35: =$R$3/($I$1-3) -> 344810.38 | K35: =IFERROR((VLOOKUP(D35,Sheet1!$B$3:$C$58,2,0)*$R$3),0) -> 643566.08 | L35: 0 | M35: =SUM(J35:L35) -> 988376.46
A36: 32 | B36: T.211272 | C36: STAF | D36: IWAN RANGGA KUSUMA | E36: AKTIF | F36: GRESIK | G36: L | I36: 32 | J36: =$R$3/($I$1-3) -> 344810.38 | K36: =IFERROR((VLOOKUP(D36,Sheet1!$B$3:$C$58,2,0)*$R$3),0) -> 883227.41 | L36: 0 | M36: =SUM(J36:L36) -> 1228037.8
A37: 33 | B37: T.221310 | C37: STAF | D37: JAFRINDA REZA ELTRICO | E37: AKTIF | F37: GRESIK | G37: L | I37: 33 | J37: =$R$3/($I$1-3) -> 344810.38 | K37: =IFERROR((VLOOKUP(D37,Sheet1!$B$3:$C$58,2,0)*$R$3),0) -> 981996.92 | L37: 0 | M37: =SUM(J37:L37) -> 1326807.3
A38: 34 | B38: T.205221 | C38: ASMAN | D38: JOKO PURWANTO,SE | E38: AKTIF | F38: GRESIK | G38: L | I38: 34 | J38: =$R$3/($I$1-3) -> 344810.38 | K38: =IFERROR((VLOOKUP(D38,Sheet1!$B$3:$C$58,2,0)*$R$3),0) -> 1224702.9 | L38: =$R$3*8% -> 2482634.8 | M38: =SUM(J38:L38) -> 4052148.1
A39: 35 | B39: T.960203 | C39: STAF | D39: KUSNO | E39: AKTIF | F39: GRESIK | G39: L | I39: 35 | J39: =$R$3/($I$1-3) -> 344810.38 | K39: =IFERROR((VLOOKUP(D39,Sheet1!$B$3:$C$58,2,0)*$R$3),0) -> 1194954.7 | L39: 0 | M39: =SUM(J39:L39) -> 1539765.1
A40: 36 | B40: T.215303 | C40: STAF | D40: LAKSANA MUS ARDHIANTO | E40: AKTIF | F40: GRESIK | G40: P | I40: 36 | J40: =$R$3/($I$1-3) -> 344810.38 | K40: =IFERROR((VLOOKUP(D40,Sheet1!$B$3:$C$58,2,0)*$R$3),0) -> 97205.293 | L40: 0 | M40: =SUM(J40:L40) -> 442015.68
...

Sheet Sheet1
D2: Jan | E2: Feb | F2: Mar | G2: Apr | H2: Mei | I2: Jun | J2: Jul | K2: Agt | L2: Sept | M2: Okt | N2: Nop | O2: Des | P2: Jml
B3: ABDUL RAHMAN, SE | C3: =P3/$P$60 -> 0.018361916 | D3: 354166.67 | E3: 354166.67 | F3: 354166.67 | G3: 354166.67 | H3: 354166.67 | I3: 354166.67 | J3: 354166.67 | K3: 354166.67 | L3: 354166.67 | M3: 354166.67 | N3: 354166.67 | O3: 354166.67 | P3: =SUM(D3:O3) -> 4250000
B4: ACH. WACHYUDI | C4: =P4/$P$60 -> 0.032889432 | D4: 708333.33 | E4: 708333.33 | F4: 708333.33 | G4: 708333.33 | H4: 708333.33 | I4: 708333.33 | J4: 708333.33 | K4: 708333.33 | L4: 708333.33 | M4: 708333.33 | N4: 264583.33 | O4: 264583.33 | P4: =SUM(D4:O4) -> 7612500
B5: AHMAD MUKHLIS K. | C5: =P5/$P$60 -> 0.025706682 | D5: 495833.33 | E5: 495833.33 | F5: 495833.33 | G5: 495833.33 | H5: 495833.33 | I5: 495833.33 | J5: 495833.33 | K5: 495833.33 | L5: 495833.33 | M5: 495833.33 | N5: 495833.33 | O5: 495833.33 | P5: =SUM(D5:O5) -> 5950000
B6: ARDHI YUNANTO | C6: =P6/$P$60 -> 0.0091809579 | D6: 0 | E6: 0 | F6: 0 | G6: 0 | H6: 0 | I6: 0 | J6: 0 | K6: 0 | L6: 0 | M6: 708333.33 | N6: 708333.33 | O6: 708333.33 | P6: =SUM(D6:O6) -> 2125000
B7: ARI KUNCORO | C7: =P7/$P$60 -> 0.0020882179 | D7: 241666.67 | E7: 241666.67 | F7: =241666.666666667-241666.666666667 -> 0 | G7: 0 | H7: 0 | I7: 0 | J7: 0 | K7: 0 | L7: 0 | M7: 0 | N7: 0 | O7: 0 | P7: =SUM(D7:O7) -> 483333.33
B8: BAGUS ADITA | C8: =P8/$P$60 -> 0.036723832 | D8: 0 | E8: 0 | F8: 850000 | G8: 0 | H8: 1700000 | I8: 0 | J8: 850000 | K8: 1700000 | L8: 850000 | M8: 850000 | N8: 850000 | O8: 850000 | P8: =SUM(D8:O8) -> 8500000
B9: BAMBANG SYAMADJI | C9: =P9/$P$60 -> 0.0099280358 | D9: 156250 | E9: 156250 | F9: 156250 | G9: 156250 | H9: 156250 | I9: 216666.67 | J9: 216666.67 | K9: 216666.67 | L9: 216666.67 | M9: 216666.67 | N9: 216666.67 | O9: 216666.67 | P9: =SUM(D9:O9) -> 2297916.7
B10: CHOIRI,SE | C10: =P10/$P$60 -> 0.0038253991 | D10: 666666.67 | E10: 0 | F10: 0 | G10: 0 | H10: 0 | I10: 0 | J10: 0 | K10: 0 | L10: 0 | M10: 0 | N10: 0 | O10: 218750 | P10: =SUM(D10:O10) -> 885416.67
B11: DANDUNG KASIATNO | C11: =P11/$P$60 -> 0.016354706 | D11: 310416.67 | E11: 310416.67 | F11: 310416.67 | G11: 310416.67 | H11: 310416.67 | I11: 310416.67 | J11: 310416.67 | K11: 310416.67 | L11: 310416.67 | M11: 310416.67 | N11: 340625 | O11: 340625 | P11: =SUM(D11:O11) -> 3785416.7
B12: DARWANTO | C12: =P12/$P$60 -> 0.040396215 | D12: 779166.67 | E12: 779166.67 | F12: 779166.67 | G12: 779166.67 | H12: 779166.67 | I12: 779166.67 | J12: 779166.67 | K12: 779166.67 | L12: 779166.67 | M12: 779166.67 | N12: 779166.67 | O12: 779166.67 | P12: =SUM(D12:O12) -> 9350000
B13: DICKY SUSANTHO | C13: =P13/$P$60 -> 0.0081008452 | D13: 0 | E13: 0 | F13: 0 | G13: 0 | H13: 0 | I13: 0 | J13: 312500 | K13: 312500 | L13: 312500 | M13: 312500 | N13: 312500 | O13: 312500 | P13: =SUM(D13:O13) -> 1875000
B14: ENDIN TAFRIORO | C14: =P14/$P$60 -> 0.014711135 | D14: 378333.33 | E14: 378333.33 | F14: 378333.33 | G14: 378333.33 | H14: 378333.33 | I14: 378333.33 | J14: 378333.33 | K14: 378333.33 | L14: 378333.33 | M14: 0 | N14: 0 | O14: 0 | P14: =SUM(D14:O14) -> 3405000
B15: ERLY NURLIANTI | C15: =P15/$P$60 -> 0.0099046334 | D15: 186666.67 | E15: 186666.67 | F15: 186666.67 | G15: 186666.67 | H15: 186666.67 | I15: 186666.67 | J15: 186666.67 | K15: 186666.67 | L15: 186666.67 | M15: 204166.67 | N15: 204166.67 | O15: 204166.67 | P15: =SUM(D15:O15) -> 2292500
B16: FADELAN CHADARIANTO | C16: =P16/$P$60 -> 0.027650885 | D16: 533333.33 | E16: 533333.33 | F16: 533333.33 | G16: 533333.33 | H16: 533333.33 | I16: 533333.33 | J16: 533333.33 | K16: 533333.33 | L16: 533333.33 | M16: 533333.33 | N16: 533333.33 | O16: 533333.33 | P16: =SUM(D16:O16) -> 6400000
B17: GOLIK | C17: =P17/$P$60 -> 0.025706682 | D17: 495833.33 | E17: 495833.33 | F17: 495833.33 | G17: 495833.33 | H17: 495833.33 | I17: 495833.33 | J17: 495833.33 | K17: 495833.33 | L17: 495833.33 | M17: 495833.33 | N17: 495833.33 | O17: 495833.33 | P17: =SUM(D17:O17) -> 5950000
B18: HADI SANYOTO, SE | C18: =P18/$P$60 -> 0.017011775 | D18: 437500 | E18: 437500 | F18: 437500 | G18: 437500 | H18: 437500 | I18: 437500 | J18: 437500 | K18: 437500 | L18: 437500 | M18: 0 | N18: 0 | P18: =SUM(D18:O18) -> 3937500
B19: HANDOKO TEJO SAPUTRO, STp. | C19: =P19/$P$60 -> 0.0069172217 | D19: 151041.67 | E19: 151041.67 | F19: 151041.67 | G19: 151041.67 | H19: 120833.33 | I19: 120833.33 | J19: 120833.33 | K19: 120833.33 | L19: 120833.33 | M19: 120833.33 | N19: 120833.33 | O19: 151041.67 | P19: =SUM(D19:O19) -> 1601041.7
B20: HARI EKO SUSANTO, SE | C20: =P20/$P$60 -> 0.019830869 | D20: 382500 | E20: 382500 | F20: 382500 | G20: 382500 | H20: 382500 | I20: 382500 | J20: 382500 | K20: 382500 | L20: 382500 | M20: 382500 | N20: 382500 | O20: 382500 | P20: =SUM(D20:O20) -> 4590000
B21: HERMANTO | C21: =P21/$P$60 -> 0.019874074 | D21: 383333.33 | E21: 383333.33 | F21: 383333.33 | G21: 383333.33 | H21: 383333.33 | I21: 383333.33 | J21: 383333.33 | K21: 383333.33 | L21: 383333.33 | M21: 383333.33 | N21: 383333.33 | O21: 383333.33 | P21: =SUM(D21:O21) -> 4600000
B22: I DEWA PUTU CANDRA K., ST | C22: =P22/$P$60 -> 0.017929871 | D22: 345833.33 | E22: 345833.33 | F22: 345833.33 | G22: 345833.33 | H22: 345833.33 | I22: 345833.33 | J22: 345833.33 | K22: 345833.33 | L22: 345833.33 | M22: 345833.33 | N22: 345833.33 | O22: 345833.33 | P22: =SUM(D22:O22) -> 4150000
B23: ISFA' | C23: =P23/$P$60 -> 0.036723832 | D23: 708333.33 | E23: 708333.33 | F23: 708333.33 | G23: 708333.33 | H23: 708333.33 | I23: 708333.33 | J23: 708333.33 | K23: 708333.33 | L23: 708333.33 | M23: 708333.33 | N23: 708333.33 | O23: 708333.33 | P23: =SUM(D23:O23) -> 8500000
B24: ITA SUDARWATI | C24: =P24/$P$60 -> 0.020738164 | D24: 400000 | E24: 400000 | F24: 400000 | G24: 400000 | H24: 400000 | I24: 400000 | J24: 400000 | K24: 400000 | L24: 400000 | M24: 400000 | N24: 400000 | O24: 400000 | P24: =SUM(D24:O24) -> 4800000
B25: IWAN RANGGA KUSUMA | C25: =P25/$P$60 -> 0.028460969 | D25: 495833.33 | E25: 495833.33 | F25: 495833.33 | G25: 495833.33 | H25: 495833.33 | I25: 495833.33 | J25: 495833.33 | K25: 495833.33 | L25: 495833.33 | M25: 708333.33 | N25: 708333.33 | O25: 708333.33 | P25: =SUM(D25:O25) -> 6587500
B26: JAFRINDA REZA ELTRICO | C26: =P26/$P$60 -> 0.031643702 | D26: 0 | E26: 665833.33 | F26: 665833.33 | G26: 665833.33 | H26: 665833.33 | I26: 665833.33 | J26: 665833.33 | K26: 665833.33 | L26: 665833.33 | M26: 665833.33 | N26: 665833.33 | O26: 665833.33 | P26: =SUM(D26:O26) -> 7324166.7
B27: JOKO PURWANTO,SE | C27: =P27/$P$60 -> 0.039464618 | D27: 798958.33 | E27: 798958.33 | F27: 798958.33 | G27: 798958.33 | H27: 798958.33 | I27: 798958.33 | J27: 798958.33 | K27: 708333.33 | L27: 708333.33 | M27: 708333.33 | N27: 708333.33 | O27: 708333.33 | P27: =SUM(D27:O27) -> 9134375
B28: KUSNAN | C28: =P28/$P$60 -> 0.0055787821 | D28: 430416.67 | E28: 430416.67 | F28: 430416.67 | G28: 0 | H28: 0 | I28: 0 | J28: 0 | K28: 0 | L28: 0 | M28: 0 | N28: 0 | O28: 0 | P28: =SUM(D28:O28) -> 1291250
B29: KUSNO | C29: =P29/$P$60 -> 0.038506018 | D29: 754166.67 | E29: 754166.67 | F29: 754166.67 | G29: 754166.67 | H29: 754166.67 | I29: 754166.67 | J29: 754166.67 | K29: 754166.67 | L29: 754166.67 | M29: 708333.33 | N29: 708333.33 | O29: 708333.33 | P29: =SUM(D29:O29) -> 8912500
B30: LAKSANA MUS ARDHIANTO | C30: =P30/$P$60 -> 0.0031323268 | D30: 0 | E30: 0 | F30: 0 | G30: 0 | H30: 0 | I30: 0 | J30: 120833.33 | K30: 120833.33 | L30: 120833.33 | M30: 120833.33 | N30: 120833.33 | O30: 120833.33 | P30: =SUM(D30:O30) -> 725000
... B58: YUDI ISFANDIYARI | C58: =P58/$P$60 -> 0.0090729466 | D58: 125000 | E58: 125000 | F58: 125000 | G58: 125000 | H58: 125000 | I58: 125000 | J58: 125000 | K58: 125000 | L58: 125000 | M58: 125000 | N58: 425000 | O58: 425000 | P58: =SUM(D58:O58) -> 2100000
L59: 0
B60: Jumlah Jasa | D60: =SUM(D3:D58) -> 19490417 | E60: =SUM(E3:E58) -> 19682083 | F60: =SUM(F3:F58) -> 20323958 | G60: =SUM(G3:G58) -> 19043542 | H60: =SUM(H3:H58) -> 20355139 | I60: =SUM(I3:I58) -> 18322847 | J60: =SUM(J3:J58) -> 19606181 | K60: =SUM(K3:K58) -> 20365556 | ... P60: =SUM(P3:P58) -> 2.3145733e+08
B61: Selisih | D61: =+D60-D62 -> 0 | E61: =+E60-E62 -> 0 | F61: =+F60-F62 -> 0.66666666 | G61: =+G60-G62 -> 0 | H61: =+H60-H62 -> -3.3527613e-08 | I61: =+I60-I62 -> -4.4703484e-08 | J61: =+J60-J62 -> -1110000 | K61: =+K60-K62 -> 3.7252903e-08 | ... O61: =+O60-O62 -> 0 | P61: =SUM(D61:O61) -> 890000.89
B62: Worksheet | D62: 19490417 | E62: 19682083 | F62: 20323958 | G62: 19043542 | H62: 20355139 | I62: 18322847 | J62: 20716181 | K62: 20365556 | L62: 18648889 | M62: 18604722 | N62: 16491181 | O62: 18522816 | P62: =SUM(D62:O62) -> 2.3056733e+08
J64: GCS lebih TF | N64: Suto Kurang
