Workbook
Name ACC: #REF!
Name ACC: #REF!
Name ACC: #REF!
Name ACC: #REF!
Name ACCOUNT: #REF!
Name ACCOUNT: #REF!
Name ACCOUNT: #REF!
Name ACCOUNT: #REF!
Name AKUN: #REF!
Name AKUN: #REF!
Name AKUN: #REF!
Name AKUN: #REF!
Name AKUNDUA: #REF!
Name AKUNDUA: #REF!
Name AKUNDUA: #REF!
Name AKUNDUA: #REF!
Name AKUNEMPAT: #REF!
Name AKUNEMPAT: #REF!
Name AKUNEMPAT: #REF!
Name AKUNEMPAT: #REF!
Name akunlima: [1]AKUNLIMA!$A$2:$C$310
Name AKUNTIGA: #REF!
Name AKUNTIGA: #REF!
Name AKUNTIGA: #REF!
Name AKUNTIGA: #REF!
Name asa: #REF!
Name asa: #REF!
Name JAN: #REF!
Name JAN: #REF!
Name JAN: #REF!
Name JAN: #REF!
Name OMSET: #REF!
Name OMSET: #REF!
Name OMSET: #REF!
Name OMSET: #REF!

Sheet NR
B2: NERACA
B3: K K C S
B4: TAHUN 2023 - 2026
B6: No | C6: Uraian | D6: PER | E6: PER | F6: PER | G6: PER | H6: PER | I6: No | J6: Uraian | K6: =D6 -> PER | L6: =E6 -> PER | M6: =F6 -> PER | N6: =G6 -> PER | O6: =H6 -> PER
D7: 31 Desember 2022 | E7: 31 Desember 2023 | F7: 31 Desember 2024 | G7: 31 Desember 2025 | H7: 31 Januari 2026 | K7: =D7 -> 31 Desember 2022 | L7: =E7 -> 31 Desember 2023 | M7: =F7 -> 31 Desember 2024 | N7: =G7 -> 31 Desember 2025 | O7: =H7 -> 31 Januari 2026
B8: I | C8: Aset Lancar | I8: VII | J8: Liabilitas Jangka Pendek
C9: Kas | D9: 22964481 | E9: 5751013.7 | F9: 1788563.7 | G9: 8851508.7 | H9: ='WS Trial balance'!BZ7 -> 4827416.7 | J9: Simpanan Sukarela I | K9: 0 | L9: 0 | M9: 0 | N9: 0 | O9: 0
C10: Bank | D10: 38487372 | E10: 53412528 | F10: 42405266 | G10: 3.0295667e+08 | H10: ='WS Trial balance'!BZ8 -> 1.9671383e+08 | J10: Simpanan Sukarela II | K10: 0 | L10: 0 | M10: 0 | N10: 0 | O10: 0
C11: Surat Berharga | D11: 0 | E11: 0 | F11: 0 | G11: 0 | H11: ='WS Trial balance'!CA9 -> 0 | J11: Utang Anggota | K11: 0 | L11: 0 | M11: 0 | N11: 0 | O11: 0
C12: Piutang Anggota | D12: 1.5707596e+09 | E12: 1.7547836e+09 | F12: 1.9778942e+09 | G12: 1.9264197e+09 | H12: =+'WS Trial balance'!BZ10 -> 1.979003e+09 | J12: Utang Non Anggota | K12: 6033860000 | L12: 6164854500 | M12: 2850000000 | N12: 300000000 | O12: =+'WS Trial balance'!CA31 -> 300000000
C13: Piutang Non Anggota | D13: 6561449467 | E13: 6.7210876e+09 | F13: 3335823867 | G13: 643143867 | H13: =+'WS Trial balance'!BZ11 -> 698023867
C14: Cad. Penyisihan | D14: -75000000 | E14: -155000000 | F14: -164000000 | G14: -182000000 | H14: =-'WS Trial balance'!CA12 -> -194000000 | J14: Utang Pajak | K14: 0 | L14: 5244487.6 | M14: 29607286 | N14: 47686535 | O14: =+'WS Trial balance'!CA36 -> 17636043
C15: Biaya yg Dibayar Dimuka | D15: 0 | E15: 0 | F15: 0 | G15: 0 | H15: ='WS Trial balance'!BZ15 -> 11608500 | J15: Utang Bunga | K15: 0 | L15: 0 | M15: 0 | N15: 0 | O15: 0
C16: Uang Muka Pembelian | D16: 0 | E16: 0 | F16: 0 | G16: 0 | H16: 0 | J16: Utang Bank | K16: 0 | L16: 0 | M16: 0 | N16: 0 | O16: 0
C17: Uang Muka Operasional | D17: 0 | E17: 0 | F17: 0 | G17: 0 | H17: 0 | J17: Utang Lain-Lain | K17: 0 | L17: 0 | M17: 0 | N17: 21680000 | O17: =+'WS Trial balance'!CA35 -> 21680000
C18: Uang Muka Pajak | D18: 0 | E18: 0 | F18: 0 | G18: 0 | H18: 0 | J18: Biaya YMHD | K18: 0 | L18: 0 | M18: 0 | N18: 0 | O18: =+'WS Trial balance'!CA37 -> 28950000
C19: Total Aset Lancar : | D19: =SUM(D9:D18) -> 8.1186609e+09 | E19: =SUM(E9:E18) -> 8.3800348e+09 | F19: =SUM(F9:F18) -> 5.1939119e+09 | G19: =SUM(G9:G18) -> 2.6993717e+09 | H19: =SUM(H9:H18) -> 2.6961766e+09 | J19: Uang Muka Penjualan | K19: 0 | L19: 0 | M19: 0 | N19: 0 | O19: 0
B20: II | C20: Penyertaan Modal | D20: 0 | E20: 0 | F20: 0 | G20: 0 | H20: 0 | K20: 0 | L20: 0 | M20: 0 | N20: 0 | O20: 0
B21: III | C21: Aktiva Pajak Tangguhan | D21: 0 | E21: 0 | F21: 0 | G21: 0 | H21: 0 | K21: 0 | L21: 0 | M21: 0 | N21: 0 | O21: 0
B22: IV | C22: Aset Tetap Berwujud | J22: Grand Total Liabilitas | K22: =SUM(K9:K21) -> 6033860000 | L22: =SUM(L9:L21) -> 6.170099e+09 | M22: =SUM(M9:M21) -> 2.8796073e+09 | N22: =SUM(N9:N21) -> 3.6936654e+08 | O22: =SUM(O9:O21) -> 3.6826604e+08
C23: Tanah | D23: 0 | E23: 0 | F23: 0 | G23: 0 | H23: 0 | I23: VIII | J23: Ekuitas
C24: Bangunan dan Instalasi Listrik | D24: 0 | E24: 0 | F24: 0 | G24: 0 | H24: 0 | J24: Simpanan Pokok | K24: 10900000 | L24: 10100000 | M24: 9500000 | N24: 7900000 | O24: =+'WS Trial balance'!CA43 -> 7900000
C25: Kendaraan | D25: 0 | E25: 0 | F25: 0 | G25: 0 | H25: 0 | J25: Wajib | K25: 306200000 | L25: 335950000 | M25: 364570000 | N25: 339030000 | O25: =+'WS Trial balance'!CA44 -> 354610000
C26: Mesin dan Peralatan | D26: 0 | E26: 0 | F26: 0 | G26: 0 | H26: 0 | J26: Hibah | K26: 0 | L26: 0 | M26: 0 | N26: 0 | O26: 0
C27: Inventaris Kantor | D27: 0 | E27: 0 | F27: 0 | G27: 0 | H27: 0 | J27: Cadangan | K27: 1623304769 | L27: 1.6810632e+09 | M27: 1.7530277e+09 | N27: 1.8279105e+09 | O27: =+'WS Trial balance'!CA46 -> 1.8914004e+09
C28: Nilai Perolehan | D28: =SUM(D23:D27) -> 0 | E28: =SUM(E23:E27) -> 0 | F28: =SUM(F23:F27) -> 0 | G28: =SUM(G23:G27) -> 0 | H28: =SUM(H23:H27) -> 0 | J28: Laba Belum dicadangkan | K28: 0 | L28: 0 | M28: 0 | N28: -1.4901161e-07 | O28: =+'WS Trial balance'!CA47 -> -447322.96
C29: Akumulasi Penyusutan Aktiva Tetap | D29: 0 | E29: 0 | F29: 0 | G29: 0 | H29: 0
C30: Total Aset Lancar : | D30: =D28+D29 -> 0 | E30: =E28+E29 -> 0 | F30: =F28+F29 -> 0 | G30: =G28+G29 -> 0 | H30: =H28+H29 -> 0 | J30: SHU | K30: 1.4439615e+08 | L30: 1.8282255e+08 | M30: 1.8720697e+08 | N30: 1.5516467e+08 | O30: =+'WS Trial balance'!BZ70 -> 74447522
B31: V | C31: Aset Tetap Tak Berwujud | J31: Total Ekuitas : | K31: =SUM(K24:K30) -> 2.0848009e+09 | L31: =SUM(L24:L30) -> 2.2099358e+09 | M31: =SUM(M24:M30) -> 2.3143047e+09 | N31: =SUM(N24:N30) -> 2.3300052e+09 | O31: =SUM(O24:O30) -> 2.3279106e+09
C32: Software Komputer | D32: 0 | E32: 0 | F32: 0 | G32: 0 | H32: 0
C33: Ak. Amrt. Software Komputer | D33: 0 | E33: 0 | F33: 0 | G33: 0 | H33: 0
C34: Total Aset Tetap Tak Berwujud : | D34: =SUM(D32:D33) -> 0 | E34: =SUM(E32:E33) -> 0 | F34: =SUM(F32:F33) -> 0 | G34: =SUM(G32:G33) -> 0 | H34: =SUM(H32:H33) -> 0
B35: VI | C35: Aset Lain-lain | D35: 0 | E35: 0 | F35: 0 | G35: 0 | H35: 0
B37: Grand Total Aset | D37: =D19+D20+D21+D30+D34+D35 -> 8.1186609e+09 | E37: =E19+E20+E21+E30+E34+E35 -> 8.3800348e+09 | F37: =F19+F20+F21+F30+F34+F35 -> 5.1939119e+09 | G37: =G19+G20+G21+G30+G34+G35 -> 2.6993717e+09 | H37: =H19+H20+H21+H30+H34+H35 -> 2.6961766e+09 | I37: Grand Total Liabilitas dan Ekuitas | K37: =K22+K31 -> 8.1186609e+09 | L37: =L22+L31 -> 8.3800348e+09 | M37: =M22+M31 -> 5.1939119e+09 | N37: =N22+N31 -> 2.6993717e+09 | O37: =O22+O31 -> 2.6961766e+09
K39: =+K37-D37 -> 0 | L39: =+L37-E37 -> 0 | M39: =+M37-F37 -> 0 | N39: =+N37-G37 -> 0 | O39: =+O37-H37 -> 0
L40: =L30-K30 -> 38426408 | M40: =M30-L30 -> 4384414.1 | N40: =N30-M30 -> -32042295 | O40: =O30-M30 -> -1.1275945e+08
K42: =K30*60% -> 86637688 | L42: =L30*60% -> 1.0969353e+08 | M42: =M30*60% -> 1.1232418e+08 | N42: =N30*60% -> 93098804 | O42: =O30*60% -> 44668513
K43: =K30-K42 -> 57758458 | L43: =L30-L42 -> 73129022 | M43: =M30-M42 -> 74882787 | N43: =N30-N42 -> 62065869 | O43: =O30-O42 -> 29779009

Sheet LR
B2: LAPORAN LABA / (RUGI)
B3: K K C S
B4: =NR!B4 -> TAHUN 2023 - 2026 | F4: l-m | H4: q-r | J4: s-t | L4: u-v | N4: w-x | P4: y-z | R4: aa-ab | T4: ac-ad | V4: ae-af | X4: ag-ah | Z4: ai-aj
D5: j-k | F5: o-p | H5: t-u | J5: y-z | L5: ad-ae | N5: ai-aj | P5: an-ao | R5: as-at | T5: ax-ay | V5: bc-bd | X5: bh-bi | Z5: bm-bn
B6: KETERANGAN | D6: JANUARI | F6: FEBRUARI | H6: MARET | J6: APRIL | L6: MEI | N6: JUNI | P6: JULI | R6: AGUSTUS | T6: SEPTEMBER | V6: OKTOBER | X6: NOPEMBER | Z6: DESEMBER | AC6: 2024
D7: =LEFT(D6,3) -> JAN | E7: ="sd. "&D7 -> sd. JAN | F7: =LEFT(F6,3) -> FEB | G7: ="sd. "&F7 -> sd. FEB | H7: =LEFT(H6,3) -> MAR | I7: ="sd. "&H7 -> sd. MAR | J7: =LEFT(J6,3) -> APR | K7: ="sd. "&J7 -> sd. APR | L7: =LEFT(L6,3) -> MEI | M7: ="sd. "&L7 -> sd. MEI | N7: =LEFT(N6,3) -> JUN | O7: ="sd. "&N7 -> sd. JUN | P7: =LEFT(P6,3) -> JUL | Q7: ="sd. "&P7 -> sd. JUL | R7: =LEFT(R6,5) -> AGUST | S7: ="sd. "&R7 -> sd. AGUST | T7: =LEFT(T6,4) -> SEPT | U7: ="sd. "&T7 -> sd. SEPT | V7: =LEFT(V6,3) -> OKT | W7: ="sd. "&V7 -> sd. OKT | X7: =LEFT(X6,3) -> NOP | Y7: ="sd. "&X7 -> sd. NOP | Z7: =LEFT(Z6,3) -> DES | AA7: ="sd. "&Z7 -> sd. DES
C8: Pendapatan
C9: Pinjaman Rutin | D9: ='WS Trial balance'!K58-'WS Trial balance'!J58 -> 78721705 | E9: =D9 -> 78721705 | F9: ='WS Trial balance'!P58-'WS Trial balance'!O58 -> 80206566 | G9: =E9+F9 -> 1.5892827e+08 | H9: ='WS Trial balance'!U58-'WS Trial balance'!T58 -> 81022330 | I9: =G9+H9 -> 2.399506e+08 | J9: ='WS Trial balance'!Z58-'WS Trial balance'!Y58 -> 77958441 | K9: =I9+J9 -> 3.1790904e+08 | L9: ='WS Trial balance'!AE58-'WS Trial balance'!AD58 -> 81143163 | M9: =K9+L9 -> 3.990522e+08 | N9: ='WS Trial balance'!AJ58-'WS Trial balance'!AI58 -> 82725663 | O9: =M9+N9 -> 4.8177787e+08 | P9: ='WS Trial balance'!AO58-'WS Trial balance'!AN58 -> 84316497 | Q9: =O9+P9 -> 5.6609436e+08 | R9: ='WS Trial balance'!AT58-'WS Trial balance'!AS58 -> 84316497 | S9: =Q9+R9 -> 6.5041086e+08 | T9: ='WS Trial balance'!AY58-'WS Trial balance'!AX58 -> 0 | U9: =S9+T9 -> 6.5041086e+08 | V9: ='WS Trial balance'!BD58-'WS Trial balance'!BC58 -> 0 | W9: =U9+V9 -> 6.5041086e+08 | X9: ='WS Trial balance'!BI58-'WS Trial balance'!BH58 -> 0 | Y9: =W9+X9 -> 6.5041086e+08 | Z9: ='WS Trial balance'!BN58-'WS Trial balance'!BM58 -> 0 | AA9: =Y9+Z9 -> 6.5041086e+08 | AB9: =AA9-AC9 -> 0 | AC9: =D9+F9+H9+J9+L9+N9+P9+R9+T9+V9+X9+Z9 -> 6.5041086e+08
C10: Pinjaman Khusus | D10: ='WS Trial balance'!K59-'WS Trial balance'!J59 -> 0 | E10: =D10 -> 0 | F10: ='WS Trial balance'!P59-'WS Trial balance'!O59 -> 0 | G10: =E10+F10 -> 0 | H10: ='WS Trial balance'!U59-'WS Trial balance'!T59 -> 0 | I10: =G10+H10 -> 0 | J10: ='WS Trial balance'!Z59-'WS Trial balance'!Y59 -> 0 | K10: =I10+J10 -> 0 | L10: ='WS Trial balance'!AE59-'WS Trial balance'!AD59 -> 0 | M10: =K10+L10 -> 0 | N10: ='WS Trial balance'!AJ59-'WS Trial balance'!AI59 -> 0 | O10: =M10+N10 -> 0 | P10: ='WS Trial balance'!AO59-'WS Trial balance'!AN59 -> 0 | Q10: =O10+P10 -> 0 | R10: ='WS Trial balance'!AT59-'WS Trial balance'!AS59 -> 0 | S10: =Q10+R10 -> 0 | T10: ='WS Trial balance'!AY59-'WS Trial balance'!AX59 -> 0 | U10: =S10+T10 -> 0 | V10: ='WS Trial balance'!BD59-'WS Trial balance'!BC59 -> 0 | W10: =U10+V10 -> 0 | X10: ='WS Trial balance'!BI59-'WS Trial balance'!BH59 -> 0 | Y10: =W10+X10 -> 0 | Z10: ='WS Trial balance'!BN59-'WS Trial balance'!BM59 -> 0 | AA10: =Y10+Z10 -> 0 | AB10: =AA10-AC10 -> 0 | AC10: =D10+F10+H10+J10+L10+N10+P10+R10+T10+V10+X10+Z10 -> 0
C11: Pinjaman Lain | D11: ='WS Trial balance'!K60-'WS Trial balance'!J60 -> 525000 | E11: =D11 -> 525000 | F11: ='WS Trial balance'!P60-'WS Trial balance'!O60 -> 350000 | G11: =E11+F11 -> 875000 | H11: ='WS Trial balance'!U60-'WS Trial balance'!T60 -> -92500 | I11: =G11+H11 -> 782500 | J11: ='WS Trial balance'!Z60-'WS Trial balance'!Y60 -> 385000 | K11: =I11+J11 -> 1167500 | L11: ='WS Trial balance'!AE60-'WS Trial balance'!AD60 -> 630000 | M11: =K11+L11 -> 1797500 | N11: ='WS Trial balance'!AJ60-'WS Trial balance'!AI60 -> 221500 | O11: =M11+N11 -> 2019000 | P11: ='WS Trial balance'!AO60-'WS Trial balance'!AN60 -> 0 | Q11: =O11+P11 -> 2019000 | R11: ='WS Trial balance'!AT60-'WS Trial balance'!AS60 -> 210000 | S11: =Q11+R11 -> 2229000 | T11: ='WS Trial balance'!AY60-'WS Trial balance'!AX60 -> 0 | U11: =S11+T11 -> 2229000 | V11: ='WS Trial balance'!BD60-'WS Trial balance'!BC60 -> 0 | W11: =U11+V11 -> 2229000 | X11: ='WS Trial balance'!BI60-'WS Trial balance'!BH60 -> 0 | Y11: =W11+X11 -> 2229000 | Z11: ='WS Trial balance'!BN60-'WS Trial balance'!BM60 -> 0 | AA11: =Y11+Z11 -> 2229000 | AB11: =AA11-AC11 -> 0 | AC11: =D11+F11+H11+J11+L11+N11+P11+R11+T11+V11+X11+Z11 -> 2229000
C12: HPP Pinj. Rutin | D12: =-'WS Trial balance'!J61+'WS Trial balance'!K61 -> -60419861 | E12: =D12 -> -60419861 | F12: =-'WS Trial balance'!O61+'WS Trial balance'!P61 -> -61858750 | G12: =E12+F12 -> -1.2227861e+08 | H12: =-'WS Trial balance'!T61+'WS Trial balance'!U61 -> -62264306 | I12: =G12+H12 -> -1.8454292e+08 | J12: =-'WS Trial balance'!Y61+'WS Trial balance'!Z61 -> -59901806 | K12: =I12+J12 -> -2.4444472e+08 | L12: =-'WS Trial balance'!AD61+'WS Trial balance'!AE61 -> -62749028 | M12: =K12+L12 -> -307193750 | N12: =-'WS Trial balance'!AI61+'WS Trial balance'!AJ61 -> -63894861 | O12: =M12+N12 -> -3.7108861e+08 | P12: =-'WS Trial balance'!AN61+'WS Trial balance'!AO61 -> -65128194 | Q12: =O12+P12 -> -4.3621681e+08 | R12: =-'WS Trial balance'!AS61+'WS Trial balance'!AT61 -> -65128194 | S12: =Q12+R12 -> -5.01345e+08 | T12: =-'WS Trial balance'!AX61+'WS Trial balance'!AY61 -> 0 | U12: =S12+T12 -> -5.01345e+08 | V12: =-'WS Trial balance'!BC61+'WS Trial balance'!BD61 -> 0 | W12: =U12+V12 -> -5.01345e+08 | X12: =-'WS Trial balance'!BH61+'WS Trial balance'!BI61 -> 0 | Y12: =W12+X12 -> -5.01345e+08 | Z12: =-'WS Trial balance'!BM61+'WS Trial balance'!BN61 -> 0 | AA12: =Y12+Z12 -> -5.01345e+08 | AB12: =AA12-AC12 -> 0 | AC12: =D12+F12+H12+J12+L12+N12+P12+R12+T12+V12+X12+Z12 -> -5.01345e+08
C13: HPP Pinj. Khusus | D13: =-'WS Trial balance'!J62+'WS Trial balance'!K62 -> 0 | E13: =D13 -> 0 | F13: =-'WS Trial balance'!O62+'WS Trial balance'!P62 -> 0 | G13: =E13+F13 -> 0 | H13: =-'WS Trial balance'!T62+'WS Trial balance'!U62 -> 0 | I13: =G13+H13 -> 0 | J13: =-'WS Trial balance'!Y62+'WS Trial balance'!Z62 -> 0 | K13: =I13+J13 -> 0 | L13: =-'WS Trial balance'!AD62+'WS Trial balance'!AE62 -> 0 | M13: =K13+L13 -> 0 | N13: =-'WS Trial balance'!AI62+'WS Trial balance'!AJ62 -> 0 | O13: =M13+N13 -> 0 | P13: =-'WS Trial balance'!AN62+'WS Trial balance'!AO62 -> 0 | Q13: =O13+P13 -> 0 | R13: =-'WS Trial balance'!AS62+'WS Trial balance'!AT62 -> 0 | S13: =Q13+R13 -> 0 | T13: =-'WS Trial balance'!AX62+'WS Trial balance'!AY62 -> 0 | U13: =S13+T13 -> 0 | V13: =-'WS Trial balance'!BC62+'WS Trial balance'!BD62 -> 0 | W13: =U13+V13 -> 0 | X13: =-'WS Trial balance'!BH62+'WS Trial balance'!BI62 -> 0 | Y13: =W13+X13 -> 0 | Z13: =-'WS Trial balance'!BM62+'WS Trial balance'!BN62 -> 0 | AA13: =Y13+Z13 -> 0 | AB13: =AA13-AC13 -> 0 | AC13: =D13+F13+H13+J13+L13+N13+P13+R13+T13+V13+X13+Z13 -> 0
C14: HPP Pinj. Lain | D14: =-'WS Trial balance'!J63+'WS Trial balance'!K63 -> 0 | E14: =D14 -> 0 | F14: =-'WS Trial balance'!O63+'WS Trial balance'!P63 -> 0 | G14: =E14+F14 -> 0 | H14: =-'WS Trial balance'!T63+'WS Trial balance'!U63 -> 0 | I14: =G14+H14 -> 0 | J14: =-'WS Trial balance'!Y63+'WS Trial balance'!Z63 -> 0 | K14: =I14+J14 -> 0 | L14: =-'WS Trial balance'!AD63+'WS Trial balance'!AE63 -> 0 | M14: =K14+L14 -> 0 | N14: =-'WS Trial balance'!AI63+'WS Trial balance'!AJ63 -> 0 | O14: =M14+N14 -> 0 | P14: =-'WS Trial balance'!AN63+'WS Trial balance'!AO63 -> 0 | Q14: =O14+P14 -> 0 | R14: =-'WS Trial balance'!AS63+'WS Trial balance'!AT63 -> 0 | S14: =Q14+R14 -> 0 | T14: =-'WS Trial balance'!AX63+'WS Trial balance'!AY63 -> 0 | U14: =S14+T14 -> 0 | V14: =-'WS Trial balance'!BC63+'WS Trial balance'!BD63 -> 0 | W14: =U14+V14 -> 0 | X14: =-'WS Trial balance'!BH63+'WS Trial balance'!BI63 -> 0 | Y14: =W14+X14 -> 0 | Z14: =-'WS Trial balance'!BM63+'WS Trial balance'!BN63 -> 0 | AA14: =Y14+Z14 -> 0 | AB14: =AA14-AC14 -> 0 | AC14: =D14+F14+H14+J14+L14+N14+P14+R14+T14+V14+X14+Z14 -> 0
C15: Laba kotor | D15: =SUM(D9:D14) -> 18826844 | E15: =SUM(E9:E14) -> 18826844 | F15: =SUM(F9:F14) -> 18697816 | G15: =SUM(G9:G14) -> 37524660 | H15: =SUM(H9:H14) -> 18665524 | I15: =SUM(I9:I14) -> 56190184 | J15: =SUM(J9:J14) -> 18441635 | K15: =SUM(K9:K14) -> 74631819 | ... AA15: =SUM(AA9:AA14) -> 1.5129486e+08 | AC15: =SUM(AC9:AC14) -> 1.5129486e+08
C17: Beban Usaha
C18: Beban Umum dan Administrasi | D18: =-'WS Trial balance'!J64+'WS Trial balance'!K64 -> -758000 | E18: =D18 -> -758000 | F18: =-'WS Trial balance'!O64+'WS Trial balance'!P64 -> -750000 | G18: =E18+F18 -> -1508000 | H18: =-'WS Trial balance'!T64+'WS Trial balance'!U64 -> -28557000 | I18: =G18+H18 -> -30065000 | J18: =-'WS Trial balance'!Y64+'WS Trial balance'!Z64 -> -750000 | K18: =I18+J18 -> -30815000 | L18: =-'WS Trial balance'!AD64+'WS Trial balance'!AE64 -> -42362600 | M18: =K18+L18 -> -73177600 | N18: =-'WS Trial balance'!AI64+'WS Trial balance'!AJ64 -> -3250000 | O18: =M18+N18 -> -76427600 | P18: =-'WS Trial balance'!AN64+'WS Trial balance'!AO64 -> -1120000 | Q18: =O18+P18 -> -77547600 | R18: =-'WS Trial balance'!AS64+'WS Trial balance'!AT64 -> -1900000 | S18: =Q18+R18 -> -79447600 | T18: =-'WS Trial balance'!AX64+'WS Trial balance'!AY64 -> 0 | U18: =S18+T18 -> -79447600 | V18: =-'WS Trial balance'!BC64+'WS Trial balance'!BD64 -> 0 | W18: =U18+V18 -> -79447600 | X18: =-'WS Trial balance'!BH64+'WS Trial balance'!BI64 -> 0 | Y18: =W18+X18 -> -79447600 | Z18: =-'WS Trial balance'!BM64+'WS Trial balance'!BN64 -> 0 | AA18: =Y18+Z18 -> -79447600 | AB18: =AA18-AC18 -> 0 | AC18: =D18+F18+H18+J18+L18+N18+P18+R18+T18+V18+X18+Z18 -> -79447600
C19: Jumlah Beban Usaha : | D19: =SUM(D18:D18) -> -758000 | E19: =SUM(E18:E18) -> -758000 | F19: =SUM(F18:F18) -> -750000 | G19: =SUM(G18:G18) -> -1508000 | H19: =SUM(H18:H18) -> -28557000 | I19: =SUM(I18:I18) -> -30065000 | J19: =SUM(J18:J18) -> -750000 | K19: =SUM(K18:K18) -> -30815000 | ... AA19: =SUM(AA18:AA18) -> -79447600 | AC19: =SUM(AC18:AC18) -> -79447600
C20: Laba usaha | D20: =+D15+D19 -> 18068844 | E20: =+E15+E19 -> 18068844 | F20: =+F15+F19 -> 17947816 | G20: =+G15+G19 -> 36016660 | H20: =+H15+H19 -> -9891475.7 | I20: =+I15+I19 -> 26125184 | J20: =+J15+J19 -> 17691635 | K20: =+K15+K19 -> 43816819 | ... AA20: =+AA15+AA19 -> 71847261 | AC20: =+AC15+AC19 -> 71847261
C21: Pendapatan / (Beban) di luar usaha
C22: Pendapatan Lain-lain | D22: ='WS Trial balance'!K65-'WS Trial balance'!J65 -> 3918000 | E22: =D22 -> 3918000 | F22: ='WS Trial balance'!P65-'WS Trial balance'!O65 -> 1423167.3 | G22: =E22+F22 -> 5341167.3 | H22: ='WS Trial balance'!U65-'WS Trial balance'!T65 -> 1356500 | I22: =G22+H22 -> 6697667.3 | J22: ='WS Trial balance'!Z65-'WS Trial balance'!Y65 -> 1356500 | K22: =I22+J22 -> 8054167.3 | L22: ='WS Trial balance'!AE65-'WS Trial balance'!AD65 -> 3146500 | M22: =K22+L22 -> 11200667 | N22: ='WS Trial balance'!AJ65-'WS Trial balance'!AI65 -> 1205000 | O22: =M22+N22 -> 12405667 | P22: ='WS Trial balance'!AO65-'WS Trial balance'!AN65 -> 1205000 | Q22: =O22+P22 -> 13610667 | R22: ='WS Trial balance'!AT65-'WS Trial balance'!AS65 -> 1205000 | S22: =Q22+R22 -> 14815667 | T22: ='WS Trial balance'!AY65-'WS Trial balance'!AX65 -> 0 | U22: =S22+T22 -> 14815667 | V22: ='WS Trial balance'!BD65-'WS Trial balance'!BC65 -> 0 | W22: =U22+V22 -> 14815667 | X22: ='WS Trial balance'!BI65-'WS Trial balance'!BH65 -> 0 | Y22: =W22+X22 -> 14815667 | Z22: ='WS Trial balance'!BN65-'WS Trial balance'!BM65 -> 0 | AA22: =Y22+Z22 -> 14815667 | AB22: =AA22-AC22 -> 0 | AC22: =D22+F22+H22+J22+L22+N22+P22+R22+T22+V22+X22+Z22 -> 14815667
C23: Biaya Lain-lain | D23: =-'WS Trial balance'!J66+'WS Trial balance'!K66 -> -1495669.1 | E23: =D23 -> -1495669.1 | F23: =-'WS Trial balance'!O66+'WS Trial balance'!P66 -> -1489907.3 | G23: =E23+F23 -> -2985576.4 | H23: =-'WS Trial balance'!T66+'WS Trial balance'!U66 -> -1541782.7 | I23: =G23+H23 -> -4527359.1 | J23: =-'WS Trial balance'!Y66+'WS Trial balance'!Z66 -> -1526806.1 | K23: =I23+J23 -> -6054165.1 | L23: =-'WS Trial balance'!AD66+'WS Trial balance'!AE66 -> -1534334.9 | M23: =K23+L23 -> -7588500 | N23: =-'WS Trial balance'!AI66+'WS Trial balance'!AJ66 -> -1552978.1 | O23: =M23+N23 -> -9141478.1 | P23: =-'WS Trial balance'!AN66+'WS Trial balance'!AO66 -> -1544455.2 | Q23: =O23+P23 -> -10685933 | R23: =-'WS Trial balance'!AS66+'WS Trial balance'!AT66 -> -1529472.7 | S23: =Q23+R23 -> -12215406 | T23: =-'WS Trial balance'!AX66+'WS Trial balance'!AY66 -> 0 | U23: =S23+T23 -> -12215406 | V23: =-'WS Trial balance'!BC66+'WS Trial balance'!BD66 -> 0 | W23: =U23+V23 -> -12215406 | X23: =-'WS Trial balance'!BH66+'WS Trial balance'!BI66 -> 0 | Y23: =W23+X23 -> -12215406 | Z23: =-'WS Trial balance'!BM66+'WS Trial balance'!BN66 -> 0 | AA23: =Y23+Z23 -> -12215406 | AB23: =AA23-AC23 -> 0 | AC23: =D23+F23+H23+J23+L23+N23+P23+R23+T23+V23+X23+Z23 -> -12215406
C24: Jumlah Pendapatan/(Beban) di luar usaha: | D24: =SUM(D22:D23) -> 2422330.9 | E24: =SUM(E22:E23) -> 2422330.9 | F24: =SUM(F22:F23) -> -66739.939 | G24: =SUM(G22:G23) -> 2355590.9 | H24: =SUM(H22:H23) -> -185282.67 | I24: =SUM(I22:I23) -> 2170308.3 | J24: =SUM(J22:J23) -> -170306.06 | K24: =SUM(K22:K23) -> 2000002.2 | ... AA24: =SUM(AA22:AA23) -> 2600261.3 | AC24: =SUM(AC22:AC23) -> 2600261.3
C25: Laba Sebelum Pajak | D25: =+D20+D24 -> 20491175 | E25: =+E20+E24 -> 20491175 | F25: =+F20+F24 -> 17881076 | G25: =+G20+G24 -> 38372251 | H25: =+H20+H24 -> -10076758 | I25: =+I20+I24 -> 28295492 | J25: =+J20+J24 -> 17521329 | K25: =+K20+K24 -> 45816822 | ... AA25: =+AA20+AA24 -> 74447522 | AC25: =+AC20+AC24 -> 74447522 | AE25: =AC25*22% -> 16378455
C26: Beban Pajak | D26: =-'WS Trial balance'!J67+'WS Trial balance'!K67 -> 0 | E26: =D26 -> 0 | F26: =-'WS Trial balance'!O67+'WS Trial balance'!P67 -> 0 | G26: =E26+F26 -> 0 | H26: =-'WS Trial balance'!T67+'WS Trial balance'!U67 -> 0 | I26: =G26+H26 -> 0 | J26: =-'WS Trial balance'!Y67+'WS Trial balance'!Z67 -> 0 | K26: =I26+J26 -> 0 | L26: =-'WS Trial balance'!AD67+'WS Trial balance'!AE67 -> 0 | M26: =K26+L26 -> 0 | N26: =-'WS Trial balance'!AI67+'WS Trial balance'!AJ67 -> 0 | O26: =M26+N26 -> 0 | P26: =-'WS Trial balance'!AN67+'WS Trial balance'!AO67 -> 0 | Q26: =O26+P26 -> 0 | R26: =-'WS Trial balance'!AS67+'WS Trial balance'!AT67 -> 0 | S26: =Q26+R26 -> 0 | T26: =-'WS Trial balance'!AX67+'WS Trial balance'!AY67 -> 0 | U26: =S26+T26 -> 0 | V26: =-'WS Trial balance'!BC67+'WS Trial balance'!BD67 -> 0 | W26: =U26+V26 -> 0 | X26: =-'WS Trial balance'!BH67+'WS Trial balance'!BI67 -> 0 | Y26: =W26+X26 -> 0 | Z26: =-'WS Trial balance'!BM67+'WS Trial balance'!BN67 -> 0 | AA26: =Y26+Z26 -> 0 | AB26: =AA26-AC26 -> 0 | AC26: =D26+F26+H26+J26+L26+N26+P26+R26+T26+V26+X26+Z26 -> 0
C27: Laba Setelah Pajak | D27: =SUM(D25:D26) -> 20491175 | E27: =SUM(E25:E26) -> 20491175 | F27: =SUM(F25:F26) -> 17881076 | G27: =SUM(G25:G26) -> 38372251 | H27: =SUM(H25:H26) -> -10076758 | I27: =SUM(I25:I26) -> 28295492 | J27: =SUM(J25:J26) -> 17521329 | K27: =SUM(K25:K26) -> 45816822 | ... AA27: =SUM(AA25:AA26) -> 74447522 | AC27: =SUM(AC25:AC26) -> 74447522
E29: =E27-'WS Trial balance'!L70 -> 0 | G29: =G27-'WS Trial balance'!Q70 -> 0 | I29: =I27-'WS Trial balance'!V70 -> 0 | K29: =K27-'WS Trial balance'!AA70 -> 0 | M29: =M27-'WS Trial balance'!AF70 -> 0 | O29: =O27-'WS Trial balance'!AK70 -> 0 | Q29: =Q27-'WS Trial balance'!AP70 -> 0 | S29: =S27-'WS Trial balance'!AU70 -> 0 | U29: =U27-'WS Trial balance'!AZ70 -> 0 | W29: =W27-'WS Trial balance'!BE70 -> 0 | Y29: =Y27-'WS Trial balance'!BJ70 -> 0 | AA29: =AA27-'WS Trial balance'!BO70 -> 0

Sheet WS Trial balance
C3: KOPERASI KARYAWAN CIPTA SEJAHTERA
C4: BALANCE SHEET, TAHUN 2026
C5: ACCOUNT | F5: KODE | G5: SALDO AWAL 2026 | J5: MUTASI JANUARI 2026 | L5: SALDO AKHIR JANUARI 2026 | O5: MUTASI FEBRUARI 2026 | Q5: SALDO AKHIR FEBRUARI 2026 | T5: MUTASI MARET 2026 | V5: SALDO AKHIR MARET 2026 | Y5: MUTASI APRIL 2026 | AA5: SALDO AKHIR APRIL 2026 | AD5: MUTASI MEI 2026 | AF5: SALDO AKHIR MEI 2026 | AI5: MUTASI JUNI 2026 | AK5: SALDO AKHIR JUNI 2026 | AN5: MUTASI JULI 2026 | AP5: SALDO AKHIR JULI 2026 | AS5: MUTASI AGUSTUS 2026 | AU5: SALDO AKHIR AGUSTUS 2026 | AX5: MUTASI SEPTEMBER 2026 | AZ5: SALDO AKHIR SEPTEMBER 2026 | BC5: MUTASI OKTOBER 2026 | BE5: SALDO AKHIR OKTOBER 2026 | BH5: MUTASI NOPEMBER 2026 | BJ5: SALDO AKHIR NOPEMBER 2026 | BM5: MUTASI DESEMBER 2026 | BO5: SALDO AKHIR DESEMBER 2026 | BT5: SALDO AWAL 2026 | BW5: MUTASI 2026 | BZ5: SALDO AKHIR 2026
G6: DEBET | H6: KREDIT | J6: DEBET | K6: KREDIT | L6: DEBET | M6: KREDIT | O6: DEBET | P6: KREDIT | Q6: DEBET | R6: KREDIT | T6: DEBET | U6: KREDIT | V6: DEBET | W6: KREDIT | Y6: DEBET | Z6: KREDIT | AA6: DEBET | AB6: KREDIT | AD6: DEBET | AE6: KREDIT | AF6: DEBET | AG6: KREDIT | AI6: DEBET | AJ6: KREDIT | AK6: DEBET | AL6: KREDIT | AN6: DEBET | AO6: KREDIT | AP6: DEBET | AQ6: KREDIT | AS6: DEBET | AT6: KREDIT | AU6: DEBET | AV6: KREDIT | AX6: DEBET | AY6: KREDIT | AZ6: DEBET | BA6: KREDIT | BC6: DEBET | BD6: KREDIT | BE6: DEBET | BF6: KREDIT | BH6: DEBET | BI6: KREDIT | BJ6: DEBET | BK6: KREDIT | BM6: DEBET | BN6: KREDIT | BO6: DEBET | BP6: KREDIT | BT6: DEBET | BU6: KREDIT | BW6: DEBET | BX6: KREDIT | BZ6: DEBET | CA6: KREDIT
D7: A01 | E7: KAS | F7: D | G7: 8851508.7 | H7: 0 | J7: =SUMIF('MUTASI 2026'!$B$5:$B$160,'WS Trial balance'!$D7,'MUTASI 2026'!$G$5:$G$160) -> 4865000 | K7: =SUMIF('MUTASI 2026'!$B$5:$B$160,'WS Trial balance'!$D7,'MUTASI 2026'!$H$5:$H$160) -> 5258000 | L7: =IF(F7="D",(G7-H7+J7-K7),0) -> 8458508.7 | M7: =IF(F7="K",(-G7+H7-J7+K7),0) -> 0 | O7: =SUMIF('MUTASI 2026'!$B$162:$B$252,'WS Trial balance'!$D7,'MUTASI 2026'!$G$162:$G$252) -> 49051500 | P7: =SUMIF('MUTASI 2026'!$B$162:$B$252,'WS Trial balance'!$D7,'MUTASI 2026'!$H$162:$H$252) -> 24350000 | Q7: =IF(F7="D",(L7-M7+O7-P7),0) -> 33160009 | R7: =IF(F7="K",(-L7+M7-O7+P7),0) -> 0 | T7: =SUMIF('MUTASI 2026'!$B$254:$B$356,'WS Trial balance'!$D7,'MUTASI 2026'!$G$254:$G$356) -> 2047000 | U7: =SUMIF('MUTASI 2026'!$B$254:$B$356,'WS Trial balance'!$D7,'MUTASI 2026'!$H$254:$H$356) -> 28557000 | V7: =IF(F7="D",(Q7-R7+T7-U7),0) -> 6650008.7 | W7: =IF(F7="K",(-Q7+R7-T7+U7),0) -> 0 | Y7: =SUMIF('MUTASI 2026'!$B$358:$B$480,'WS Trial balance'!$D7,'MUTASI 2026'!$G$358:$G$480) -> 4136000 | Z7: =SUMIF('MUTASI 2026'!$B$358:$B$480,'WS Trial balance'!$D7,'MUTASI 2026'!$H$358:$H$480) -> 6250000 | AA7: =IF(F7="D",(V7-W7+Y7-Z7),0) -> 4536008.7 | AB7: =IF(F7="K",(-V7+W7-Y7+Z7),0) -> 0 | AD7: =SUMIF('MUTASI 2026'!$B$482:$B$655,'WS Trial balance'!$D7,'MUTASI 2026'!$G$482:$G$655) -> 62358000 | AE7: =SUMIF('MUTASI 2026'!$B$482:$B$655,'WS Trial balance'!$D7,'MUTASI 2026'!$H$482:$H$655) -> 65179638 | AF7: =IF(F7="D",(AA7-AB7+AD7-AE7),0) -> 1714370.7 | AG7: =IF(F7="K",(-AA7+AB7-AD7+AE7),0) -> 0 | AI7: =SUMIF('MUTASI 2026'!$B$657:$B$748,'WS Trial balance'!$D7,'MUTASI 2026'!$G$657:$G$748) -> 12626000 | AJ7: =SUMIF('MUTASI 2026'!$B$657:$B$748,'WS Trial balance'!$D7,'MUTASI 2026'!$H$657:$H$748) -> 17250000 | AK7: =IF(F7="D",(AF7-AG7+AI7-AJ7),0) -> -2909629.3 | AL7: =IF(F7="K",(-AF7+AG7-AI7+AJ7),0) -> 0 | AN7: =SUMIF('MUTASI 2026'!$B$750:$B$851,'WS Trial balance'!$D7,'MUTASI 2026'!$G$750:$G$851) -> 12745500 | AO7: =SUMIF('MUTASI 2026'!$B$750:$B$851,'WS Trial balance'!$D7,'MUTASI 2026'!$H$750:$H$851) -> 6120000 | AP7: =IF(F7="D",(AK7-AL7+AN7-AO7),0) -> 3715870.7 | AQ7: =IF(F7="K",(-AK7+AL7-AN7+AO7),0) -> 0 | AS7: =SUMIF('MUTASI 2026'!$B$853:$B$945,'WS Trial balance'!$D7,'MUTASI 2026'!$G$853:$G$945) -> 28245000 | AT7: =SUMIF('MUTASI 2026'!$B$853:$B$945,'WS Trial balance'!$D7,'MUTASI 2026'!$H$853:$H$945) -> 27133454 | AU7: =IF(F7="D",(AP7-AQ7+AS7-AT7),0) -> 4827416.7 | AV7: =IF(F7="K",(-AP7+AQ7-AS7+AT7),0) -> 0 | AX7: =SUMIF('MUTASI 2026'!$B$1274:$B$1379,'WS Trial balance'!$D7,'MUTASI 2026'!$G$1274:$G$1379) -> 0 | AY7: =SUMIF('MUTASI 2026'!$B$1274:$B$1379,'WS Trial balance'!$D7,'MUTASI 2026'!$H$1274:$H$1379) -> 0 | AZ7: =IF(F7="D",(AU7-AV7+AX7-AY7),0) -> 4827416.7 | BA7: =IF(F7="K",(-AU7+AV7-AX7+AY7),0) -> 0 | BC7: =SUMIF('MUTASI 2026'!$B$1382:$B$1477,'WS Trial balance'!$D7,'MUTASI 2026'!$G$1382:$G$1477) -> 0 | BD7: =SUMIF('MUTASI 2026'!$B$1382:$B$1477,'WS Trial balance'!$D7,'MUTASI 2026'!$H$1382:$H$1477) -> 0 | BE7: =IF(F7="D",(AZ7-BA7+BC7-BD7),0) -> 4827416.7 | BF7: =IF(F7="K",(-AZ7+BA7-BC7+BD7),0) -> 0 | BH7: =SUMIF('MUTASI 2026'!$B$1480:$B$1600,'WS Trial balance'!$D7,'MUTASI 2026'!$G$1480:$G$1600) -> 0 | BI7: =SUMIF('MUTASI 2026'!$B$1480:$B$1600,'WS Trial balance'!$D7,'MUTASI 2026'!$H$1480:$H$1600) -> 0 | BJ7: =IF(F7="D",(BE7-BF7+BH7-BI7),0) -> 4827416.7 | BK7: =IF(F7="K",(-BE7+BF7-BH7+BI7),0) -> 0 | BM7: =SUMIF('MUTASI 2026'!$B$1603:$B$1722,'WS Trial balance'!$D7,'MUTASI 2026'!$G$1603:$G$1722) -> 0 | BN7: =SUMIF('MUTASI 2026'!$B$1603:$B$1722,'WS Trial balance'!$D7,'MUTASI 2026'!$H$1603:$H$1722) -> 0 | BO7: =IF(F7="D",(BJ7-BK7+BM7-BN7),0) -> 4827416.7 | BP7: =IF(F7="K",(-BJ7+BK7-BM7+BN7),0) -> 0 | BT7: =G7 -> 8851508.7 | BU7: =H7 -> 0 | BW7: =J7+O7+T7+Y7+AD7+AI7+AN7+AS7+AX7+BC7+BH7+BM7 -> 176074000 | BX7: =K7+P7+U7+Z7+AE7+AJ7+AO7+AT7+AY7+BD7+BI7+BN7 -> 180098092 | BZ7: =IF(F7="D",(BT7-BU7+BW7-BX7),0) -> 4827416.7 | CA7: =IF(F7="K",(-BT7+BU7-BW7+BX7),0) -> 0
D8: A02 | E8: BANK | F8: D | G8: 3.0295667e+08 | H8: 0 | J8: =SUMIF('MUTASI 2026'!$B$5:$B$160,'WS Trial balance'!$D8,'MUTASI 2026'!$G$5:$G$160) -> 1.6096184e+08 | K8: =SUMIF('MUTASI 2026'!$B$5:$B$160,'WS Trial balance'!$D8,'MUTASI 2026'!$H$5:$H$160) -> 150561132 | L8: =IF(F8="D",(G8-H8+J8-K8),0) -> 3.1335738e+08 | M8: =IF(F8="K",(-G8+H8-J8+K8),0) -> 0 | O8: =SUMIF('MUTASI 2026'!$B$162:$B$252,'WS Trial balance'!$D8,'MUTASI 2026'!$G$162:$G$252) -> 93516226 | P8: =SUMIF('MUTASI 2026'!$B$162:$B$252,'WS Trial balance'!$D8,'MUTASI 2026'!$H$162:$H$252) -> 185549733 | Q8: =IF(F8="D",(L8-M8+O8-P8),0) -> 2.2132388e+08 | R8: =IF(F8="K",(-L8+M8-O8+P8),0) -> 0 | T8: =SUMIF('MUTASI 2026'!$B$254:$B$356,'WS Trial balance'!$D8,'MUTASI 2026'!$G$254:$G$356) -> 200552329 | U8: =SUMIF('MUTASI 2026'!$B$254:$B$356,'WS Trial balance'!$D8,'MUTASI 2026'!$H$254:$H$356) -> 1.6824743e+08 | V8: =IF(F8="D",(Q8-R8+T8-U8),0) -> 2.5362878e+08 | W8: =IF(F8="K",(-Q8+R8-T8+U8),0) -> 0 | Y8: =SUMIF('MUTASI 2026'!$B$358:$B$480,'WS Trial balance'!$D8,'MUTASI 2026'!$G$358:$G$480) -> 1.3277787e+08 | Z8: =SUMIF('MUTASI 2026'!$B$358:$B$480,'WS Trial balance'!$D8,'MUTASI 2026'!$H$358:$H$480) -> 115116400 | AA8: =IF(F8="D",(V8-W8+Y8-Z8),0) -> 2.7129025e+08 | AB8: =IF(F8="K",(-V8+W8-Y8+Z8),0) -> 0 | AD8: =SUMIF('MUTASI 2026'!$B$482:$B$655,'WS Trial balance'!$D8,'MUTASI 2026'!$G$482:$G$655) -> 1.3562463e+08 | AE8: =SUMIF('MUTASI 2026'!$B$482:$B$655,'WS Trial balance'!$D8,'MUTASI 2026'!$H$482:$H$655) -> 258347801 | AF8: =IF(F8="D",(AA8-AB8+AD8-AE8),0) -> 1.4856708e+08 | AG8: =IF(F8="K",(-AA8+AB8-AD8+AE8),0) -> 0 | AI8: =SUMIF('MUTASI 2026'!$B$657:$B$748,'WS Trial balance'!$D8,'MUTASI 2026'!$G$657:$G$748) -> 262975576 | AJ8: =SUMIF('MUTASI 2026'!$B$657:$B$748,'WS Trial balance'!$D8,'MUTASI 2026'!$H$657:$H$748) -> 1.9024789e+08 | AK8: =IF(F8="D",(AF8-AG8+AI8-AJ8),0) -> 2.2129476e+08 | AL8: =IF(F8="K",(-AF8+AG8-AI8+AJ8),0) -> 0 | AN8: =SUMIF('MUTASI 2026'!$B$750:$B$851,'WS Trial balance'!$D8,'MUTASI 2026'!$G$750:$G$851) -> 119526496 | AO8: =SUMIF('MUTASI 2026'!$B$750:$B$851,'WS Trial balance'!$D8,'MUTASI 2026'!$H$750:$H$851) -> 1.0601945e+08 | AP8: =IF(F8="D",(AK8-AL8+AN8-AO8),0) -> 2.348018e+08 | AQ8: =IF(F8="K",(-AK8+AL8-AN8+AO8),0) -> 0 | AS8: =SUMIF('MUTASI 2026'!$B$853:$B$945,'WS Trial balance'!$D8,'MUTASI 2026'!$G$853:$G$945) -> 88167024 | AT8: =SUMIF('MUTASI 2026'!$B$853:$B$945,'WS Trial balance'!$D8,'MUTASI 2026'!$H$853:$H$945) -> 126255000 | AU8: =IF(F8="D",(AP8-AQ8+AS8-AT8),0) -> 1.9671383e+08 | AV8: =IF(F8="K",(-AP8+AQ8-AS8+AT8),0) -> 0 | AX8: =SUMIF('MUTASI 2026'!$B$1274:$B$1379,'WS Trial balance'!$D8,'MUTASI 2026'!$G$1274:$G$1379) -> 0 | AY8: =SUMIF('MUTASI 2026'!$B$1274:$B$1379,'WS Trial balance'!$D8,'MUTASI 2026'!$H$1274:$H$1379) -> 0 | AZ8: =IF(F8="D",(AU8-AV8+AX8-AY8),0) -> 1.9671383e+08 | BA8: =IF(F8="K",(-AU8+AV8-AX8+AY8),0) -> 0 | BC8: =SUMIF('MUTASI 2026'!$B$1382:$B$1477,'WS Trial balance'!$D8,'MUTASI 2026'!$G$1382:$G$1477) -> 0 | BD8: =SUMIF('MUTASI 2026'!$B$1382:$B$1477,'WS Trial balance'!$D8,'MUTASI 2026'!$H$1382:$H$1477) -> 0 | BE8: =IF(F8="D",(AZ8-BA8+BC8-BD8),0) -> 1.9671383e+08 | BF8: =IF(F8="K",(-AZ8+BA8-BC8+BD8),0) -> 0 | BH8: =SUMIF('MUTASI 2026'!$B$1480:$B$1600,'WS Trial balance'!$D8,'MUTASI 2026'!$G$1480:$G$1600) -> 0 | BI8: =SUMIF('MUTASI 2026'!$B$1480:$B$1600,'WS Trial balance'!$D8,'MUTASI 2026'!$H$1480:$H$1600) -> 0 | BJ8: =IF(F8="D",(BE8-BF8+BH8-BI8),0) -> 1.9671383e+08 | BK8: =IF(F8="K",(-BE8+BF8-BH8+BI8),0) -> 0 | BM8: =SUMIF('MUTASI 2026'!$B$1603:$B$1722,'WS Trial balance'!$D8,'MUTASI 2026'!$G$1603:$G$1722) -> 0 | BN8: =SUMIF('MUTASI 2026'!$B$1603:$B$1722,'WS Trial balance'!$D8,'MUTASI 2026'!$H$1603:$H$1722) -> 0 | BO8: =IF(F8="D",(BJ8-BK8+BM8-BN8),0) -> 1.9671383e+08 | BP8: =IF(F8="K",(-BJ8+BK8-BM8+BN8),0) -> 0 | BT8: =G8 -> 3.0295667e+08 | BU8: =H8 -> 0 | BW8: =J8+O8+T8+Y8+AD8+AI8+AN8+AS8+AX8+BC8+BH8+BM8 -> 1.194102e+09 | BX8: =K8+P8+U8+Z8+AE8+AJ8+AO8+AT8+AY8+BD8+BI8+BN8 -> 1.3003448e+09 | BZ8: =IF(F8="D",(BT8-BU8+BW8-BX8),0) -> 1.9671383e+08 | CA8: =IF(F8="K",(-BT8+BU8-BW8+BX8),0) -> 0
D9: A03 | E9: SURAT BERHARGA | F9: D | G9: 0 | H9: 0 | J9: =SUMIF('MUTASI 2026'!$B$5:$B$160,'WS Trial balance'!$D9,'MUTASI 2026'!$G$5:$G$160) -> 0 | K9: =SUMIF('MUTASI 2026'!$B$5:$B$160,'WS Trial balance'!$D9,'MUTASI 2026'!$H$5:$H$160) -> 0 | L9: =IF(F9="D",(G9-H9+J9-K9),0) -> 0 | M9: =IF(F9="K",(-G9+H9-J9+K9),0) -> 0 | O9: =SUMIF('MUTASI 2026'!$B$162:$B$252,'WS Trial balance'!$D9,'MUTASI 2026'!$G$162:$G$252) -> 0 | P9: =SUMIF('MUTASI 2026'!$B$162:$B$252,'WS Trial balance'!$D9,'MUTASI 2026'!$H$162:$H$252) -> 0 | Q9: =IF(F9="D",(L9-M9+O9-P9),0) -> 0 | R9: =IF(F9="K",(-L9+M9-O9+P9),0) -> 0 | T9: =SUMIF('MUTASI 2026'!$B$254:$B$356,'WS Trial balance'!$D9,'MUTASI 2026'!$G$254:$G$356) -> 0 | U9: =SUMIF('MUTASI 2026'!$B$254:$B$356,'WS Trial balance'!$D9,'MUTASI 2026'!$H$254:$H$356) -> 0 | V9: =IF(F9="D",(Q9-R9+T9-U9),0) -> 0 | W9: =IF(F9="K",(-Q9+R9-T9+U9),0) -> 0 | Y9: =SUMIF('MUTASI 2026'!$B$358:$B$480,'WS Trial balance'!$D9,'MUTASI 2026'!$G$358:$G$480) -> 0 | Z9: =SUMIF('MUTASI 2026'!$B$358:$B$480,'WS Trial balance'!$D9,'MUTASI 2026'!$H$358:$H$480) -> 0 | AA9: =IF(F9="D",(V9-W9+Y9-Z9),0) -> 0 | AB9: =IF(F9="K",(-V9+W9-Y9+Z9),0) -> 0 | AD9: =SUMIF('MUTASI 2026'!$B$482:$B$655,'WS Trial balance'!$D9,'MUTASI 2026'!$G$482:$G$655) -> 0 | AE9: =SUMIF('MUTASI 2026'!$B$482:$B$655,'WS Trial balance'!$D9,'MUTASI 2026'!$H$482:$H$655) -> 0 | AF9: =IF(F9="D",(AA9-AB9+AD9-AE9),0) -> 0 | AG9: =IF(F9="K",(-AA9+AB9-AD9+AE9),0) -> 0 | AI9: =SUMIF('MUTASI 2026'!$B$657:$B$748,'WS Trial balance'!$D9,'MUTASI 2026'!$G$657:$G$748) -> 0 | AJ9: =SUMIF('MUTASI 2026'!$B$657:$B$748,'WS Trial balance'!$D9,'MUTASI 2026'!$H$657:$H$748) -> 0 | AK9: =IF(F9="D",(AF9-AG9+AI9-AJ9),0) -> 0 | AL9: =IF(F9="K",(-AF9+AG9-AI9+AJ9),0) -> 0 | AN9: =SUMIF('MUTASI 2026'!$B$750:$B$851,'WS Trial balance'!$D9,'MUTASI 2026'!$G$750:$G$851) -> 0 | AO9: =SUMIF('MUTASI 2026'!$B$750:$B$851,'WS Trial balance'!$D9,'MUTASI 2026'!$H$750:$H$851) -> 0 | AP9: =IF(F9="D",(AK9-AL9+AN9-AO9),0) -> 0 | AQ9: =IF(F9="K",(-AK9+AL9-AN9+AO9),0) -> 0 | AS9: =SUMIF('MUTASI 2026'!$B$853:$B$945,'WS Trial balance'!$D9,'MUTASI 2026'!$G$853:$G$945) -> 0 | AT9: =SUMIF('MUTASI 2026'!$B$853:$B$945,'WS Trial balance'!$D9,'MUTASI 2026'!$H$853:$H$945) -> 0 | AU9: =IF(F9="D",(AP9-AQ9+AS9-AT9),0) -> 0 | AV9: =IF(F9="K",(-AP9+AQ9-AS9+AT9),0) -> 0 | AX9: =SUMIF('MUTASI 2026'!$B$1274:$B$1379,'WS Trial balance'!$D9,'MUTASI 2026'!$G$1274:$G$1379) -> 0 | AY9: =SUMIF('MUTASI 2026'!$B$1274:$B$1379,'WS Trial balance'!$D9,'MUTASI 2026'!$H$1274:$H$1379) -> 0 | AZ9: =IF(F9="D",(AU9-AV9+AX9-AY9),0) -> 0 | BA9: =IF(F9="K",(-AU9+AV9-AX9+AY9),0) -> 0 | BC9: =SUMIF('MUTASI 2026'!$B$1382:$B$1477,'WS Trial balance'!$D9,'MUTASI 2026'!$G$1382:$G$1477) -> 0 | BD9: =SUMIF('MUTASI 2026'!$B$1382:$B$1477,'WS Trial balance'!$D9,'MUTASI 2026'!$H$1382:$H$1477) -> 0 | BE9: =IF(F9="D",(AZ9-BA9+BC9-BD9),0) -> 0 | BF9: =IF(F9="K",(-AZ9+BA9-BC9+BD9),0) -> 0 | BH9: =SUMIF('MUTASI 2026'!$B$1480:$B$1600,'WS Trial balance'!$D9,'MUTASI 2026'!$G$1480:$G$1600) -> 0 | BI9: =SUMIF('MUTASI 2026'!$B$1480:$B$1600,'WS Trial balance'!$D9,'MUTASI 2026'!$H$1480:$H$1600) -> 0 | BJ9: =IF(F9="D",(BE9-BF9+BH9-BI9),0) -> 0 | BK9: =IF(F9="K",(-BE9+BF9-BH9+BI9),0) -> 0 | BM9: =SUMIF('MUTASI 2026'!$B$1603:$B$1722,'WS Trial balance'!$D9,'MUTASI 2026'!$G$1603:$G$1722) -> 0 | BN9: =SUMIF('MUTASI 2026'!$B$1603:$B$1722,'WS Trial balance'!$D9,'MUTASI 2026'!$H$1603:$H$1722) -> 0 | BO9: =IF(F9="D",(BJ9-BK9+BM9-BN9),0) -> 0 | BP9: =IF(F9="K",(-BJ9+BK9-BM9+BN9),0) -> 0 | BT9: =G9 -> 0 | BU9: =H9 -> 0 | BW9: =J9+O9+T9+Y9+AD9+AI9+AN9+AS9+AX9+BC9+BH9+BM9 -> 0 | BX9: =K9+P9+U9+Z9+AE9+AJ9+AO9+AT9+AY9+BD9+BI9+BN9 -> 0 | BZ9: =IF(F9="D",(BT9-BU9+BW9-BX9),0) -> 0 | CA9: =IF(F9="K",(-BT9+BU9-BW9+BX9),0) -> 0
D10: A04A | E10: PIUTANG ANGGOTA | F10: D | G10: 1.9264197e+09 | H10: 0 | J10: =SUMIF('MUTASI 2026'!$B$5:$B$160,'WS Trial balance'!$D10,'MUTASI 2026'!$G$5:$G$160) -> 284500000 | K10: =SUMIF('MUTASI 2026'!$B$5:$B$160,'WS Trial balance'!$D10,'MUTASI 2026'!$H$5:$H$160) -> 2.3192654e+08 | L10: =IF(F10="D",(G10-H10+J10-K10),0) -> 1.9789932e+09 | M10: =IF(F10="K",(-G10+H10-J10+K10),0) -> 0 | O10: =SUMIF('MUTASI 2026'!$B$162:$B$252,'WS Trial balance'!$D10,'MUTASI 2026'!$G$162:$G$252) -> 1.55e+08 | P10: =SUMIF('MUTASI 2026'!$B$162:$B$252,'WS Trial balance'!$D10,'MUTASI 2026'!$H$162:$H$252) -> 91326917 | Q10: =IF(F10="D",(L10-M10+O10-P10),0) -> 2.0426662e+09 | R10: =IF(F10="K",(-L10+M10-O10+P10),0) -> 0 | T10: =SUMIF('MUTASI 2026'!$B$254:$B$356,'WS Trial balance'!$D10,'MUTASI 2026'!$G$254:$G$356) -> 50000000 | U10: =SUMIF('MUTASI 2026'!$B$254:$B$356,'WS Trial balance'!$D10,'MUTASI 2026'!$H$254:$H$356) -> 1.6440381e+08 | V10: =IF(F10="D",(Q10-R10+T10-U10),0) -> 1.9282624e+09 | W10: =IF(F10="K",(-Q10+R10-T10+U10),0) -> 0 | Y10: =SUMIF('MUTASI 2026'!$B$358:$B$480,'WS Trial balance'!$D10,'MUTASI 2026'!$G$358:$G$480) -> 119500000 | Z10: =SUMIF('MUTASI 2026'!$B$358:$B$480,'WS Trial balance'!$D10,'MUTASI 2026'!$H$358:$H$480) -> 1.2398614e+08 | AA10: =IF(F10="D",(V10-W10+Y10-Z10),0) -> 1.9237763e+09 | AB10: =IF(F10="K",(-V10+W10-Y10+Z10),0) -> 0 | AD10: =SUMIF('MUTASI 2026'!$B$482:$B$655,'WS Trial balance'!$D10,'MUTASI 2026'!$G$482:$G$655) -> 278000000 | AE10: =SUMIF('MUTASI 2026'!$B$482:$B$655,'WS Trial balance'!$D10,'MUTASI 2026'!$H$482:$H$655) -> 2.2368703e+08 | AF10: =IF(F10="D",(AA10-AB10+AD10-AE10),0) -> 1.9780893e+09 | AG10: =IF(F10="K",(-AA10+AB10-AD10+AE10),0) -> 0 | AI10: =SUMIF('MUTASI 2026'!$B$657:$B$748,'WS Trial balance'!$D10,'MUTASI 2026'!$G$657:$G$748) -> 19000000 | AJ10: =SUMIF('MUTASI 2026'!$B$657:$B$748,'WS Trial balance'!$D10,'MUTASI 2026'!$H$657:$H$748) -> 66299361 | AK10: =IF(F10="D",(AF10-AG10+AI10-AJ10),0) -> 1.9307899e+09 | AL10: =IF(F10="K",(-AF10+AG10-AI10+AJ10),0) -> 0 | AN10: =SUMIF('MUTASI 2026'!$B$750:$B$851,'WS Trial balance'!$D10,'MUTASI 2026'!$G$750:$G$851) -> 274000000 | AO10: =SUMIF('MUTASI 2026'!$B$750:$B$851,'WS Trial balance'!$D10,'MUTASI 2026'!$H$750:$H$851) -> 2.5537369e+08 | AP10: =IF(F10="D",(AK10-AL10+AN10-AO10),0) -> 1.9494162e+09 | AQ10: =IF(F10="K",(-AK10+AL10-AN10+AO10),0) -> 0 | AS10: =SUMIF('MUTASI 2026'!$B$853:$B$945,'WS Trial balance'!$D10,'MUTASI 2026'!$G$853:$G$945) -> 125000000 | AT10: =SUMIF('MUTASI 2026'!$B$853:$B$945,'WS Trial balance'!$D10,'MUTASI 2026'!$H$853:$H$945) -> 95413194 | AU10: =IF(F10="D",(AP10-AQ10+AS10-AT10),0) -> 1.979003e+09 | AV10: =IF(F10="K",(-AP10+AQ10-AS10+AT10),0) -> 0 | AX10: =SUMIF('MUTASI 2026'!$B$1274:$B$1379,'WS Trial balance'!$D10,'MUTASI 2026'!$G$1274:$G$1379) -> 0 | AY10: =SUMIF('MUTASI 2026'!$B$1274:$B$1379,'WS Trial balance'!$D10,'MUTASI 2026'!$H$1274:$H$1379) -> 0 | AZ10: =IF(F10="D",(AU10-AV10+AX10-AY10),0) -> 1.979003e+09 | BA10: =IF(F10="K",(-AU10+AV10-AX10+AY10),0) -> 0 | BC10: =SUMIF('MUTASI 2026'!$B$1382:$B$1477,'WS Trial balance'!$D10,'MUTASI 2026'!$G$1382:$G$1477) -> 0 | BD10: =SUMIF('MUTASI 2026'!$B$1382:$B$1477,'WS Trial balance'!$D10,'MUTASI 2026'!$H$1382:$H$1477) -> 0 | BE10: =IF(F10="D",(AZ10-BA10+BC10-BD10),0) -> 1.979003e+09 | BF10: =IF(F10="K",(-AZ10+BA10-BC10+BD10),0) -> 0 | BH10: =SUMIF('MUTASI 2026'!$B$1480:$B$1600,'WS Trial balance'!$D10,'MUTASI 2026'!$G$1480:$G$1600) -> 0 | BI10: =SUMIF('MUTASI 2026'!$B$1480:$B$1600,'WS Trial balance'!$D10,'MUTASI 2026'!$H$1480:$H$1600) -> 0 | BJ10: =IF(F10="D",(BE10-BF10+BH10-BI10),0) -> 1.979003e+09 | BK10: =IF(F10="K",(-BE10+BF10-BH10+BI10),0) -> 0 | BM10: =SUMIF('MUTASI 2026'!$B$1603:$B$1722,'WS Trial balance'!$D10,'MUTASI 2026'!$G$1603:$G$1722) -> 0 | BN10: =SUMIF('MUTASI 2026'!$B$1603:$B$1722,'WS Trial balance'!$D10,'MUTASI 2026'!$H$1603:$H$1722) -> 0 | BO10: =IF(F10="D",(BJ10-BK10+BM10-BN10),0) -> 1.979003e+09 | BP10: =IF(F10="K",(-BJ10+BK10-BM10+BN10),0) -> 0 | BT10: =G10 -> 1.9264197e+09 | BU10: =H10 -> 0 | BW10: =J10+O10+T10+Y10+AD10+AI10+AN10+AS10+AX10+BC10+BH10+BM10 -> 1.305e+09 | BX10: =K10+P10+U10+Z10+AE10+AJ10+AO10+AT10+AY10+BD10+BI10+BN10 -> 1.2524167e+09 | BZ10: =IF(F10="D",(BT10-BU10+BW10-BX10),0) -> 1.979003e+09 | CA10: =IF(F10="K",(-BT10+BU10-BW10+BX10),0) -> 0
D11: A04B | E11: PIUTANG NON ANGGOTA | F11: D | G11: 643143867 | H11: 0 | J11: =SUMIF('MUTASI 2026'!$B$5:$B$160,'WS Trial balance'!$D11,'MUTASI 2026'!$G$5:$G$160) -> 70560000 | K11: =SUMIF('MUTASI 2026'!$B$5:$B$160,'WS Trial balance'!$D11,'MUTASI 2026'!$H$5:$H$160) -> 78400000 | L11: =IF(F11="D",(G11-H11+J11-K11),0) -> 635303867 | M11: =IF(F11="K",(-G11+H11-J11+K11),0) -> 0 | O11: =SUMIF('MUTASI 2026'!$B$162:$B$252,'WS Trial balance'!$D11,'MUTASI 2026'!$G$162:$G$252) -> 27440000 | P11: =SUMIF('MUTASI 2026'!$B$162:$B$252,'WS Trial balance'!$D11,'MUTASI 2026'!$H$162:$H$252) -> 0 | Q11: =IF(F11="D",(L11-M11+O11-P11),0) -> 662743867 | R11: =IF(F11="K",(-L11+M11-O11+P11),0) -> 0 | T11: =SUMIF('MUTASI 2026'!$B$254:$B$356,'WS Trial balance'!$D11,'MUTASI 2026'!$G$254:$G$356) -> 27440000 | U11: =SUMIF('MUTASI 2026'!$B$254:$B$356,'WS Trial balance'!$D11,'MUTASI 2026'!$H$254:$H$356) -> 15680000 | V11: =IF(F11="D",(Q11-R11+T11-U11),0) -> 674503867 | W11: =IF(F11="K",(-Q11+R11-T11+U11),0) -> 0 | Y11: =SUMIF('MUTASI 2026'!$B$358:$B$480,'WS Trial balance'!$D11,'MUTASI 2026'!$G$358:$G$480) -> 27440000 | Z11: =SUMIF('MUTASI 2026'!$B$358:$B$480,'WS Trial balance'!$D11,'MUTASI 2026'!$H$358:$H$480) -> 15680000 | AA11: =IF(F11="D",(V11-W11+Y11-Z11),0) -> 686263867 | AB11: =IF(F11="K",(-V11+W11-Y11+Z11),0) -> 0 | AD11: =SUMIF('MUTASI 2026'!$B$482:$B$655,'WS Trial balance'!$D11,'MUTASI 2026'!$G$482:$G$655) -> 27440000 | AE11: =SUMIF('MUTASI 2026'!$B$482:$B$655,'WS Trial balance'!$D11,'MUTASI 2026'!$H$482:$H$655) -> 15680000 | AF11: =IF(F11="D",(AA11-AB11+AD11-AE11),0) -> 698023867 | AG11: =IF(F11="K",(-AA11+AB11-AD11+AE11),0) -> 0 | AI11: =SUMIF('MUTASI 2026'!$B$657:$B$748,'WS Trial balance'!$D11,'MUTASI 2026'!$G$657:$G$748) -> 15680000 | AJ11: =SUMIF('MUTASI 2026'!$B$657:$B$748,'WS Trial balance'!$D11,'MUTASI 2026'!$H$657:$H$748) -> 15680000 | AK11: =IF(F11="D",(AF11-AG11+AI11-AJ11),0) -> 698023867 | AL11: =IF(F11="K",(-AF11+AG11-AI11+AJ11),0) -> 0 | AN11: =SUMIF('MUTASI 2026'!$B$750:$B$851,'WS Trial balance'!$D11,'MUTASI 2026'!$G$750:$G$851) -> 15680000 | AO11: =SUMIF('MUTASI 2026'!$B$750:$B$851,'WS Trial balance'!$D11,'MUTASI 2026'!$H$750:$H$851) -> 31360000 | AP11: =IF(F11="D",(AK11-AL11+AN11-AO11),0) -> 682343867 | AQ11: =IF(F11="K",(-AK11+AL11-AN11+AO11),0) -> 0 | AS11: =SUMIF('MUTASI 2026'!$B$853:$B$945,'WS Trial balance'!$D11,'MUTASI 2026'!$G$853:$G$945) -> 15680000 | AT11: =SUMIF('MUTASI 2026'!$B$853:$B$945,'WS Trial balance'!$D11,'MUTASI 2026'!$H$853:$H$945) -> 0 | AU11: =IF(F11="D",(AP11-AQ11+AS11-AT11),0) -> 698023867 | AV11: =IF(F11="K",(-AP11+AQ11-AS11+AT11),0) -> 0 | AX11: =SUMIF('MUTASI 2026'!$B$1274:$B$1379,'WS Trial balance'!$D11,'MUTASI 2026'!$G$1274:$G$1379) -> 0 | AY11: =SUMIF('MUTASI 2026'!$B$1274:$B$1379,'WS Trial balance'!$D11,'MUTASI 2026'!$H$1274:$H$1379) -> 0 | AZ11: =IF(F11="D",(AU11-AV11+AX11-AY11),0) -> 698023867 | BA11: =IF(F11="K",(-AU11+AV11-AX11+AY11),0) -> 0 | BC11: =SUMIF('MUTASI 2026'!$B$1382:$B$1477,'WS Trial balance'!$D11,'MUTASI 2026'!$G$1382:$G$1477) -> 0 | BD11: =SUMIF('MUTASI 2026'!$B$1382:$B$1477,'WS Trial balance'!$D11,'MUTASI 2026'!$H$1382:$H$1477) -> 0 | BE11: =IF(F11="D",(AZ11-BA11+BC11-BD11),0) -> 698023867 | BF11: =IF(F11="K",(-AZ11+BA11-BC11+BD11),0) -> 0 | BH11: =SUMIF('MUTASI 2026'!$B$1480:$B$1600,'WS Trial balance'!$D11,'MUTASI 2026'!$G$1480:$G$1600) -> 0 | BI11: =SUMIF('MUTASI 2026'!$B$1480:$B$1600,'WS Trial balance'!$D11,'MUTASI 2026'!$H$1480:$H$1600) -> 0 | BJ11: =IF(F11="D",(BE11-BF11+BH11-BI11),0) -> 698023867 | BK11: =IF(F11="K",(-BE11+BF11-BH11+BI11),0) -> 0 | BM11: =SUMIF('MUTASI 2026'!$B$1603:$B$1722,'WS Trial balance'!$D11,'MUTASI 2026'!$G$1603:$G$1722) -> 0 | BN11: =SUMIF('MUTASI 2026'!$B$1603:$B$1722,'WS Trial balance'!$D11,'MUTASI 2026'!$H$1603:$H$1722) -> 0 | BO11: =IF(F11="D",(BJ11-BK11+BM11-BN11),0) -> 698023867 | BP11: =IF(F11="K",(-BJ11+BK11-BM11+BN11),0) -> 0 | BT11: =G11 -> 643143867 | BU11: =H11 -> 0 | BW11: =J11+O11+T11+Y11+AD11+AI11+AN11+AS11+AX11+BC11+BH11+BM11 -> 227360000 | BX11: =K11+P11+U11+Z11+AE11+AJ11+AO11+AT11+AY11+BD11+BI11+BN11 -> 172480000 | BZ11: =IF(F11="D",(BT11-BU11+BW11-BX11),0) -> 698023867 | CA11: =IF(F11="K",(-BT11+BU11-BW11+BX11),0) -> 0
D12: A05 | E12: CADANGAN PENGHAPUSAN PIUTANG USAHA | F12: K | G12: 0 | H12: 182000000 | J12: =SUMIF('MUTASI 2026'!$B$5:$B$160,'WS Trial balance'!$D12,'MUTASI 2026'!$G$5:$G$160) -> 0 | K12: =SUMIF('MUTASI 2026'!$B$5:$B$160,'WS Trial balance'!$D12,'MUTASI 2026'!$H$5:$H$160) -> 1500000 | L12: =IF(F12="D",(G12-H12+J12-K12),0) -> 0 | M12: =IF(F12="K",(-G12+H12-J12+K12),0) -> 183500000 | O12: =SUMIF('MUTASI 2026'!$B$162:$B$252,'WS Trial balance'!$D12,'MUTASI 2026'!$G$162:$G$252) -> 0 | P12: =SUMIF('MUTASI 2026'!$B$162:$B$252,'WS Trial balance'!$D12,'MUTASI 2026'!$H$162:$H$252) -> 1500000 | Q12: =IF(F12="D",(L12-M12+O12-P12),0) -> 0 | R12: =IF(F12="K",(-L12+M12-O12+P12),0) -> 185000000 | T12: =SUMIF('MUTASI 2026'!$B$254:$B$356,'WS Trial balance'!$D12,'MUTASI 2026'!$G$254:$G$356) -> 0 | U12: =SUMIF('MUTASI 2026'!$B$254:$B$356,'WS Trial balance'!$D12,'MUTASI 2026'!$H$254:$H$356) -> 1500000 | V12: =IF(F12="D",(Q12-R12+T12-U12),0) -> 0 | W12: =IF(F12="K",(-Q12+R12-T12+U12),0) -> 186500000 | Y12: =SUMIF('MUTASI 2026'!$B$358:$B$480,'WS Trial balance'!$D12,'MUTASI 2026'!$G$358:$G$480) -> 0 | Z12: =SUMIF('MUTASI 2026'!$B$358:$B$480,'WS Trial balance'!$D12,'MUTASI 2026'!$H$358:$H$480) -> 1500000 | AA12: =IF(F12="D",(V12-W12+Y12-Z12),0) -> 0 | AB12: =IF(F12="K",(-V12+W12-Y12+Z12),0) -> 188000000 | AD12: =SUMIF('MUTASI 2026'!$B$482:$B$655,'WS Trial balance'!$D12,'MUTASI 2026'!$G$482:$G$655) -> 0 | AE12: =SUMIF('MUTASI 2026'!$B$482:$B$655,'WS Trial balance'!$D12,'MUTASI 2026'!$H$482:$H$655) -> 1500000 | AF12: =IF(F12="D",(AA12-AB12+AD12-AE12),0) -> 0 | AG12: =IF(F12="K",(-AA12+AB12-AD12+AE12),0) -> 189500000 | AI12: =SUMIF('MUTASI 2026'!$B$657:$B$748,'WS Trial balance'!$D12,'MUTASI 2026'!$G$657:$G$748) -> 0 | AJ12: =SUMIF('MUTASI 2026'!$B$657:$B$748,'WS Trial balance'!$D12,'MUTASI 2026'!$H$657:$H$748) -> 1500000 | AK12: =IF(F12="D",(AF12-AG12+AI12-AJ12),0) -> 0 | AL12: =IF(F12="K",(-AF12+AG12-AI12+AJ12),0) -> 191000000 | AN12: =SUMIF('MUTASI 2026'!$B$750:$B$851,'WS Trial balance'!$D12,'MUTASI 2026'!$G$750:$G$851) -> 0 | AO12: =SUMIF('MUTASI 2026'!$B$750:$B$851,'WS Trial balance'!$D12,'MUTASI 2026'!$H$750:$H$851) -> 1500000 | AP12: =IF(F12="D",(AK12-AL12+AN12-AO12),0) -> 0 | AQ12: =IF(F12="K",(-AK12+AL12-AN12+AO12),0) -> 192500000 | AS12: =SUMIF('MUTASI 2026'!$B$853:$B$945,'WS Trial balance'!$D12,'MUTASI 2026'!$G$853:$G$945) -> 0 | AT12: =SUMIF('MUTASI 2026'!$B$853:$B$945,'WS Trial balance'!$D12,'MUTASI 2026'!$H$853:$H$945) -> 1500000 | AU12: =IF(F12="D",(AP12-AQ12+AS12-AT12),0) -> 0 | AV12: =IF(F12="K",(-AP12+AQ12-AS12+AT12),0) -> 194000000 | AX12: =SUMIF('MUTASI 2026'!$B$1274:$B$1379,'WS Trial balance'!$D12,'MUTASI 2026'!$G$1274:$G$1379) -> 0 | AY12: =SUMIF('MUTASI 2026'!$B$1274:$B$1379,'WS Trial balance'!$D12,'MUTASI 2026'!$H$1274:$H$1379) -> 0 | AZ12: =IF(F12="D",(AU12-AV12+AX12-AY12),0) -> 0 | BA12: =IF(F12="K",(-AU12+AV12-AX12+AY12),0) -> 194000000 | BC12: =SUMIF('MUTASI 2026'!$B$1382:$B$1477,'WS Trial balance'!$D12,'MUTASI 2026'!$G$1382:$G$1477) -> 0 | BD12: =SUMIF('MUTASI 2026'!$B$1382:$B$1477,'WS Trial balance'!$D12,'MUTASI 2026'!$H$1382:$H$1477) -> 0 | BE12: =IF(F12="D",(AZ12-BA12+BC12-BD12),0) -> 0 | BF12: =IF(F12="K",(-AZ12+BA12-BC12+BD12),0) -> 194000000 | BH12: =SUMIF('MUTASI 2026'!$B$1480:$B$1600,'WS Trial balance'!$D12,'MUTASI 2026'!$G$1480:$G$1600) -> 0 | BI12: =SUMIF('MUTASI 2026'!$B$1480:$B$1600,'WS Trial balance'!$D12,'MUTASI 2026'!$H$1480:$H$1600) -> 0 | BJ12: =IF(F12="D",(BE12-BF12+BH12-BI12),0) -> 0 | BK12: =IF(F12="K",(-BE12+BF12-BH12+BI12),0) -> 194000000 | BM12: =SUMIF('MUTASI 2026'!$B$1603:$B$1722,'WS Trial balance'!$D12,'MUTASI 2026'!$G$1603:$G$1722) -> 0 | BN12: =SUMIF('MUTASI 2026'!$B$1603:$B$1722,'WS Trial balance'!$D12,'MUTASI 2026'!$H$1603:$H$1722) -> 0 | BO12: =IF(F12="D",(BJ12-BK12+BM12-BN12),0) -> 0 | BP12: =IF(F12="K",(-BJ12+BK12-BM12+BN12),0) -> 194000000 | BT12: =G12 -> 0 | BU12: =H12 -> 182000000 | BW12: =J12+O12+T12+Y12+AD12+AI12+AN12+AS12+AX12+BC12+BH12+BM12 -> 0 | BX12: =K12+P12+U12+Z12+AE12+AJ12+AO12+AT12+AY12+BD12+BI12+BN12 -> 12000000 | BZ12: =IF(F12="D",(BT12-BU12+BW12-BX12),0) -> 0 | CA12: =IF(F12="K",(-BT12+BU12-BW12+BX12),0) -> 194000000
D13: A06 | E13: PIUTANG LAIN-LAIN | F13: D | G13: 0 | H13: 0 | J13: =SUMIF('MUTASI 2026'!$B$5:$B$160,'WS Trial balance'!$D13,'MUTASI 2026'!$G$5:$G$160) -> 0 | K13: =SUMIF('MUTASI 2026'!$B$5:$B$160,'WS Trial balance'!$D13,'MUTASI 2026'!$H$5:$H$160) -> 0 | L13: =IF(F13="D",(G13-H13+J13-K13),0) -> 0 | M13: =IF(F13="K",(-G13+H13-J13+K13),0) -> 0 | O13: =SUMIF('MUTASI 2026'!$B$162:$B$252,'WS Trial balance'!$D13,'MUTASI 2026'!$G$162:$G$252) -> 0 | P13: =SUMIF('MUTASI 2026'!$B$162:$B$252,'WS Trial balance'!$D13,'MUTASI 2026'!$H$162:$H$252) -> 0 | Q13: =IF(F13="D",(L13-M13+O13-P13),0) -> 0 | R13: =IF(F13="K",(-L13+M13-O13+P13),0) -> 0 | T13: =SUMIF('MUTASI 2026'!$B$254:$B$356,'WS Trial balance'!$D13,'MUTASI 2026'!$G$254:$G$356) -> 0 | U13: =SUMIF('MUTASI 2026'!$B$254:$B$356,'WS Trial balance'!$D13,'MUTASI 2026'!$H$254:$H$356) -> 0 | V13: =IF(F13="D",(Q13-R13+T13-U13),0) -> 0 | W13: =IF(F13="K",(-Q13+R13-T13+U13),0) -> 0 | Y13: =SUMIF('MUTASI 2026'!$B$358:$B$480,'WS Trial balance'!$D13,'MUTASI 2026'!$G$358:$G$480) -> 0 | Z13: =SUMIF('MUTASI 2026'!$B$358:$B$480,'WS Trial balance'!$D13,'MUTASI 2026'!$H$358:$H$480) -> 0 | AA13: =IF(F13="D",(V13-W13+Y13-Z13),0) -> 0 | AB13: =IF(F13="K",(-V13+W13-Y13+Z13),0) -> 0 | AD13: =SUMIF('MUTASI 2026'!$B$482:$B$655,'WS Trial balance'!$D13,'MUTASI 2026'!$G$482:$G$655) -> 0 | AE13: =SUMIF('MUTASI 2026'!$B$482:$B$655,'WS Trial balance'!$D13,'MUTASI 2026'!$H$482:$H$655) -> 0 | AF13: =IF(F13="D",(AA13-AB13+AD13-AE13),0) -> 0 | AG13: =IF(F13="K",(-AA13+AB13-AD13+AE13),0) -> 0 | AI13: =SUMIF('MUTASI 2026'!$B$657:$B$748,'WS Trial balance'!$D13,'MUTASI 2026'!$G$657:$G$748) -> 0 | AJ13: =SUMIF('MUTASI 2026'!$B$657:$B$748,'WS Trial balance'!$D13,'MUTASI 2026'!$H$657:$H$748) -> 0 | AK13: =IF(F13="D",(AF13-AG13+AI13-AJ13),0) -> 0 | AL13: =IF(F13="K",(-AF13+AG13-AI13+AJ13),0) -> 0 | AN13: =SUMIF('MUTASI 2026'!$B$750:$B$851,'WS Trial balance'!$D13,'MUTASI 2026'!$G$750:$G$851) -> 0 | AO13: =SUMIF('MUTASI 2026'!$B$750:$B$851,'WS Trial balance'!$D13,'MUTASI 2026'!$H$750:$H$851) -> 0 | AP13: =IF(F13="D",(AK13-AL13+AN13-AO13),0) -> 0 | AQ13: =IF(F13="K",(-AK13+AL13-AN13+AO13),0) -> 0 | AS13: =SUMIF('MUTASI 2026'!$B$853:$B$945,'WS Trial balance'!$D13,'MUTASI 2026'!$G$853:$G$945) -> 0 | AT13: =SUMIF('MUTASI 2026'!$B$853:$B$945,'WS Trial balance'!$D13,'MUTASI 2026'!$H$853:$H$945) -> 0 | AU13: =IF(F13="D",(AP13-AQ13+AS13-AT13),0) -> 0 | AV13: =IF(F13="K",(-AP13+AQ13-AS13+AT13),0) -> 0 | AX13: =SUMIF('MUTASI 2026'!$B$1274:$B$1379,'WS Trial balance'!$D13,'MUTASI 2026'!$G$1274:$G$1379) -> 0 | AY13: =SUMIF('MUTASI 2026'!$B$1274:$B$1379,'WS Trial balance'!$D13,'MUTASI 2026'!$H$1274:$H$1379) -> 0 | AZ13: =IF(F13="D",(AU13-AV13+AX13-AY13),0) -> 0 | BA13: =IF(F13="K",(-AU13+AV13-AX13+AY13),0) -> 0 | BC13: =SUMIF('MUTASI 2026'!$B$1382:$B$1477,'WS Trial balance'!$D13,'MUTASI 2026'!$G$1382:$G$1477) -> 0 | BD13: =SUMIF('MUTASI 2026'!$B$1382:$B$1477,'WS Trial balance'!$D13,'MUTASI 2026'!$H$1382:$H$1477) -> 0 | BE13: =IF(F13="D",(AZ13-BA13+BC13-BD13),0) -> 0 | BF13: =IF(F13="K",(-AZ13+BA13-BC13+BD13),0) -> 0 | BH13: =SUMIF('MUTASI 2026'!$B$1480:$B$1600,'WS Trial balance'!$D13,'MUTASI 2026'!$G$1480:$G$1600) -> 0 | BI13: =SUMIF('MUTASI 2026'!$B$1480:$B$1600,'WS Trial balance'!$D13,'MUTASI 2026'!$H$1480:$H$1600) -> 0 | BJ13: =IF(F13="D",(BE13-BF13+BH13-BI13),0) -> 0 | BK13: =IF(F13="K",(-BE13+BF13-BH13+BI13),0) -> 0 | BM13: =SUMIF('MUTASI 2026'!$B$1603:$B$1722,'WS Trial balance'!$D13,'MUTASI 2026'!$G$1603:$G$1722) -> 0 | BN13: =SUMIF('MUTASI 2026'!$B$1603:$B$1722,'WS Trial balance'!$D13,'MUTASI 2026'!$H$1603:$H$1722) -> 0 | BO13: =IF(F13="D",(BJ13-BK13+BM13-BN13),0) -> 0 | BP13: =IF(F13="K",(-BJ13+BK13-BM13+BN13),0) -> 0 | BT13: =G13 -> 0 | BU13: =H13 -> 0 | BW13: =J13+O13+T13+Y13+AD13+AI13+AN13+AS13+AX13+BC13+BH13+BM13 -> 0 | BX13: =K13+P13+U13+Z13+AE13+AJ13+AO13+AT13+AY13+BD13+BI13+BN13 -> 0 | BZ13: =IF(F13="D",(BT13-BU13+BW13-BX13),0) -> 0 | CA13: =IF(F13="K",(-BT13+BU13-BW13+BX13),0) -> 0
D14: A07 | E14: UANG MUKA PEMBELIAN | F14: D | G14: 0 | H14: 0 | J14: =SUMIF('MUTASI 2026'!$B$5:$B$160,'WS Trial balance'!$D14,'MUTASI 2026'!$G$5:$G$160) -> 0 | K14: =SUMIF('MUTASI 2026'!$B$5:$B$160,'WS Trial balance'!$D14,'MUTASI 2026'!$H$5:$H$160) -> 0 | L14: =IF(F14="D",(G14-H14+J14-K14),0) -> 0 | M14: =IF(F14="K",(-G14+H14-J14+K14),0) -> 0 | O14: =SUMIF('MUTASI 2026'!$B$162:$B$252,'WS Trial balance'!$D14,'MUTASI 2026'!$G$162:$G$252) -> 0 | P14: =SUMIF('MUTASI 2026'!$B$162:$B$252,'WS Trial balance'!$D14,'MUTASI 2026'!$H$162:$H$252) -> 0 | Q14: =IF(F14="D",(L14-M14+O14-P14),0) -> 0 | R14: =IF(F14="K",(-L14+M14-O14+P14),0) -> 0 | T14: =SUMIF('MUTASI 2026'!$B$254:$B$356,'WS Trial balance'!$D14,'MUTASI 2026'!$G$254:$G$356) -> 0 | U14: =SUMIF('MUTASI 2026'!$B$254:$B$356,'WS Trial balance'!$D14,'MUTASI 2026'!$H$254:$H$356) -> 0 | V14: =IF(F14="D",(Q14-R14+T14-U14),0) -> 0 | W14: =IF(F14="K",(-Q14+R14-T14+U14),0) -> 0 | Y14: =SUMIF('MUTASI 2026'!$B$358:$B$480,'WS Trial balance'!$D14,'MUTASI 2026'!$G$358:$G$480) -> 0 | Z14: =SUMIF('MUTASI 2026'!$B$358:$B$480,'WS Trial balance'!$D14,'MUTASI 2026'!$H$358:$H$480) -> 0 | AA14: =IF(F14="D",(V14-W14+Y14-Z14),0) -> 0 | AB14: =IF(F14="K",(-V14+W14-Y14+Z14),0) -> 0 | AD14: =SUMIF('MUTASI 2026'!$B$482:$B$655,'WS Trial balance'!$D14,'MUTASI 2026'!$G$482:$G$655) -> 0 | AE14: =SUMIF('MUTASI 2026'!$B$482:$B$655,'WS Trial balance'!$D14,'MUTASI 2026'!$H$482:$H$655) -> 0 | AF14: =IF(F14="D",(AA14-AB14+AD14-AE14),0) -> 0 | AG14: =IF(F14="K",(-AA14+AB14-AD14+AE14),0) -> 0 | AI14: =SUMIF('MUTASI 2026'!$B$657:$B$748,'WS Trial balance'!$D14,'MUTASI 2026'!$G$657:$G$748) -> 0 | AJ14: =SUMIF('MUTASI 2026'!$B$657:$B$748,'WS Trial balance'!$D14,'MUTASI 2026'!$H$657:$H$748) -> 0 | AK14: =IF(F14="D",(AF14-AG14+AI14-AJ14),0) -> 0 | AL14: =IF(F14="K",(-AF14+AG14-AI14+AJ14),0) -> 0 | AN14: =SUMIF('MUTASI 2026'!$B$750:$B$851,'WS Trial balance'!$D14,'MUTASI 2026'!$G$750:$G$851) -> 0 | AO14: =SUMIF('MUTASI 2026'!$B$750:$B$851,'WS Trial balance'!$D14,'MUTASI 2026'!$H$750:$H$851) -> 0 | AP14: =IF(F14="D",(AK14-AL14+AN14-AO14),0) -> 0 | AQ14: =IF(F14="K",(-AK14+AL14-AN14+AO14),0) -> 0 | AS14: =SUMIF('MUTASI 2026'!$B$853:$B$945,'WS Trial balance'!$D14,'MUTASI 2026'!$G$853:$G$945) -> 0 | AT14: =SUMIF('MUTASI 2026'!$B$853:$B$945,'WS Trial balance'!$D14,'MUTASI 2026'!$H$853:$H$945) -> 0 | AU14: =IF(F14="D",(AP14-AQ14+AS14-AT14),0) -> 0 | AV14: =IF(F14="K",(-AP14+AQ14-AS14+AT14),0) -> 0 | AX14: =SUMIF('MUTASI 2026'!$B$1274:$B$1379,'WS Trial balance'!$D14,'MUTASI 2026'!$G$1274:$G$1379) -> 0 | AY14: =SUMIF('MUTASI 2026'!$B$1274:$B$1379,'WS Trial balance'!$D14,'MUTASI 2026'!$H$1274:$H$1379) -> 0 | AZ14: =IF(F14="D",(AU14-AV14+AX14-AY14),0) -> 0 | BA14: =IF(F14="K",(-AU14+AV14-AX14+AY14),0) -> 0 | BC14: =SUMIF('MUTASI 2026'!$B$1382:$B$1477,'WS Trial balance'!$D14,'MUTASI 2026'!$G$1382:$G$1477) -> 0 | BD14: =SUMIF('MUTASI 2026'!$B$1382:$B$1477,'WS Trial balance'!$D14,'MUTASI 2026'!$H$1382:$H$1477) -> 0 | BE14: =IF(F14="D",(AZ14-BA14+BC14-BD14),0) -> 0 | BF14: =IF(F14="K",(-AZ14+BA14-BC14+BD14),0) -> 0 | BH14: =SUMIF('MUTASI 2026'!$B$1480:$B$1600,'WS Trial balance'!$D14,'MUTASI 2026'!$G$1480:$G$1600) -> 0 | BI14: =SUMIF('MUTASI 2026'!$B$1480:$B$1600,'WS Trial balance'!$D14,'MUTASI 2026'!$H$1480:$H$1600) -> 0 | BJ14: =IF(F14="D",(BE14-BF14+BH14-BI14),0) -> 0 | BK14: =IF(F14="K",(-BE14+BF14-BH14+BI14),0) -> 0 | BM14: =SUMIF('MUTASI 2026'!$B$1603:$B$1722,'WS Trial balance'!$D14,'MUTASI 2026'!$G$1603:$G$1722) -> 0 | BN14: =SUMIF('MUTASI 2026'!$B$1603:$B$1722,'WS Trial balance'!$D14,'MUTASI 2026'!$H$1603:$H$1722) -> 0 | BO14: =IF(F14="D",(BJ14-BK14+BM14-BN14),0) -> 0 | BP14: =IF(F14="K",(-BJ14+BK14-BM14+BN14),0) -> 0 | BT14: =G14 -> 0 | BU14: =H14 -> 0 | BW14: =J14+O14+T14+Y14+AD14+AI14+AN14+AS14+AX14+BC14+BH14+BM14 -> 0 | BX14: =K14+P14+U14+Z14+AE14+AJ14+AO14+AT14+AY14+BD14+BI14+BN14 -> 0 | BZ14: =IF(F14="D",(BT14-BU14+BW14-BX14),0) -> 0 | CA14: =IF(F14="K",(-BT14+BU14-BW14+BX14),0) -> 0
